Workbook

Sheet Summary
B2: 1. 수입 from 현금입금 | D2: =SUM(D4:D6) -> 101230000 | E2: =SUM(E4:E6) -> 114674216 | K2: #0. 여행/공연비 계획 | N2: =SUM(N4:N6) -> 7500000 | O2: =SUM(O4:O6) -> 7624232 | P2: =SUM(P4:P6) -> -124232 | Q2: 잔여금액 | R2: =P2/N2 -> -0.016564267
C3: 구분 | D3: 예상 | E3: 금액 | F3: % | G3: \ | H3: 비고 | L3: 구분 | N3: 연간계획 | O3: 누적 사용금액 | P3: 잔액 | Q3: 잔여기간 | R3: =(DATE(2022,12,31)-DATE(YEAR(NOW()),MONTH(NOW()),DAY(NOW())))/365 -> -3.1369863
C4: Piece - 현금입금 | D4: =3720000*2+4200000*10+180000*2+30000*12 -> 50160000 | E4: =SUMIFS('현금입금'!H:H,'현금입금'!F:F,"입금",'현금입금'!$I:$I,"p") -> 52263152 | F4: =E4/D4 -> 1.0419289 | G4: =E4-D4 -> 2103152 | H4: 3월부터는 브랜디식대 현금입금없이 회사에서 정산 | L4: 여행 | N4: 7000000 | O4: =SUMIFS('지출내역'!$I:$I,'지출내역'!$F:$F,"여행공연비",'지출내역'!$G:$G,"국내여행")+SUMIFS('지출내역'!$I:$I,'지출내역'!$F:$F,"여행공연비",'지출내역'!$G:$G,"해외여행") -> 7624232 | P4: =N4-O4 -> -624232 | Q4: =1-IFERROR(O4/N4,"") -> -0.089176
C5: Laki - 현금입금 | D5: =3120000*12+4280000+3570000+4700000 -> 49990000 | E5: =SUMIFS('현금입금'!H:H,'현금입금'!F:F,"입금",'현금입금'!$I:$I,"l") -> 62231064 | F5: =E5/D5 -> 1.2448703 | G5: =E5-D5 -> 12241064 | L5: 문화생활 | N5: 500000 | O5: =SUMIFS('지출내역'!$I:$I,'지출내역'!$F:$F,"여행공연비",'지출내역'!$G:$G,Summary!$L5) -> 0 | P5: =N5-O5 -> 500000 | Q5: =1-IFERROR(O5/N5,"") -> 1
C6: Laki - 교원공제회 고정 | D6: =90000*12 -> 1080000 | E6: =MONTH(NOW())*90000 -> 180000 | F6: =E6/D6 -> 0.16666667 | G6: =E6-D6 -> -900000 | H6: 월 9만원 고정
B8: 2. 지출 from 지출내역 | D8: =SUM(D10:D12) -> 61882000 | E8: =SUM(E10:E12) -> 55101406
C9: 구분 | D9: 예상 | E9: 금액 | F9: % | G9: \ | H9: 비고 | K9: #1. 고정비 계획 | N9: =SUM(N11:N27) -> 34736000 | O9: =SUM(O11:O27) -> 28373758 | P9: =SUM(P11:P27) -> 6362242.5 | Q9: 잔여금액 | R9: =(P9-P23)/(N9-N23) -> 0.18695513
C10: 여행/공연비 | D10: =N2 -> 7500000 | E10: =O2 -> 7624232 | F10: =E10/D10 -> 1.0165643 | G10: =E10-D10 -> 124232 | L10: 고정비 구분 | N10: 연간계획 | O10: 누적 사용금액 | P10: 잔액 | Q10: 잔여기간 | R10: =(DATE(2022,12,31)-DATE(YEAR(NOW()),MONTH(NOW()),DAY(NOW())))/365 -> -3.1369863
C11: 고정비 | D11: =N9 -> 34736000 | E11: =O9 -> 28373758 | F11: =E11/D11 -> 0.8168401 | G11: =E11-D11 -> -6362242.5 | L11: 경조사비 | N11: 1500000 | O11: =SUMIFS('지출내역'!$I:$I,'지출내역'!$F:$F,"고정비",'지출내역'!$G:$G,Summary!$L11) -> 820000 | P11: =N11-O11 -> 680000 | Q11: =1-IFERROR(O11/N11,"") -> 0.45333333
C12: 변동비 | D12: =N31 -> 19646000 | E12: =O31 -> 19103416 | F12: =E12/D12 -> 0.97238196 | G12: =E12-D12 -> -542584 | L12: 관리비 | M12: 월평균 27만원예상 | N12: =280000*12 -> 3360000 | O12: =SUMIFS('지출내역'!$I:$I,'지출내역'!$F:$F,"고정비",'지출내역'!$G:$G,Summary!$L12) -> 3112360 | P12: =N12-O12 -> 247640 | Q12: =1-IFERROR(O12/N12,"") -> 0.073702381
L13: 교통비 | M13: 대중교통/택시비 | N13: 1000000 | O13: =SUMIFS('지출내역'!$I:$I,'지출내역'!$F:$F,"고정비",'지출내역'!$G:$G,Summary!$L13) -> 650750 | P13: =N13-O13 -> 349250 | Q13: =1-IFERROR(O13/N13,"") -> 0.34925
B14: #1. 수입 - 지출 | D14: =D2-D8 -> 39348000 | E14: =E2-E8 -> 59572810 | F14: =E14/D14 -> 1.5139984 | L14: 렌탈비 | M14: 정수기렌탈 | N14: =10900*12 -> 130800 | O14: =SUMIFS('지출내역'!$I:$I,'지출내역'!$F:$F,"고정비",'지출내역'!$G:$G,Summary!$L14) -> 111140 | P14: =N14-O14 -> 19660 | Q14: =1-IFERROR(O14/N14,"") -> 0.15030581
L15: 문경 | N15: 4000000 | O15: =SUMIFS('지출내역'!$I:$I,'지출내역'!$F:$F,"고정비",'지출내역'!$G:$G,Summary!$L15) -> 3094695 | P15: =N15-O15 -> 905305 | Q15: =1-IFERROR(O15/N15,"") -> 0.22632625
B16: 3. 저축/대출상환 | D16: =D14 -> 39348000 | E16: =SUM(E18:E22) -> 57792120 | L16: 미용 | N16: 500000 | O16: =SUMIFS('지출내역'!$I:$I,'지출내역'!$F:$F,"고정비",'지출내역'!$G:$G,Summary!$L16) -> 680850 | P16: =N16-O16 -> -180850 | Q16: =1-IFERROR(O16/N16,"") -> -0.3617
C17: 구분 | D17: 연간 예상 | E17: 금액 | F17: % | G17: \ | H17: 비고 | L17: 세금 | M17: 재산세, 지방교육세, 도시계획세 / 주민세, 자동차세 등 | N17: 1000000 | O17: =SUMIFS('지출내역'!$I:$I,'지출내역'!$F:$F,"고정비",'지출내역'!$G:$G,Summary!$L17) -> 563060 | P17: =N17-O17 -> 436940 | Q17: =1-IFERROR(O17/N17,"") -> 0.43694
C18: 교원공제회 | D18: =90000*12 -> 1080000 | E18: =MONTH(NOW())*90000 -> 180000 | F18: =IFERROR(E18/D18,0) -> 0.16666667 | G18: =E18-D18 -> -900000 | H18: 월 9만원 고정 | L18: 보험 | M18: 자동차보험, 화재보험, 실손보험 | N18: =500000+9600*12+35000*12 -> 1035200 | O18: =SUMIFS('지출내역'!$I:$I,'지출내역'!$F:$F,"고정비",'지출내역'!$G:$G,Summary!$L18) -> 992140 | P18: =N18-O18 -> 43060 | Q18: =1-IFERROR(O18/N18,"") -> 0.041595827
C19: 주택담보대출상환(원금) | D19: 3927333 | E19: =SUMIFS('지출내역'!$I:$I,'지출내역'!$F:$F,"대출상환",'지출내역'!$G:$G,"주택담보대출 원금") -> 46139925 | F19: =IFERROR(E19/D19,0) -> 11.748412 | G19: =E19-D19 -> 42212592 | L19: 통신비 | N19: 850000 | O19: =SUMIFS('지출내역'!$I:$I,'지출내역'!$F:$F,"고정비",'지출내역'!$G:$G,Summary!$L19) -> 751270 | P19: =N19-O19 -> 98730 | Q19: =1-IFERROR(O19/N19,"") -> 0.11615294
C20: 신용대출상환(원금) | D20: 0 | E20: =SUMIFS('지출내역'!$I:$I,'지출내역'!$F:$F,"대출상환",'지출내역'!$G:$G,"신용대출 원금") -> 0 | F20: =IFERROR(E20/D20,0) -> 0 | G20: =E20-D20 -> 0 | L20: 자동차운행 | M20: 주유, 하이패스, 수리, 세차 등 | N20: 2000000 | O20: =SUMIFS('지출내역'!$I:$I,'지출내역'!$F:$F,"고정비",'지출내역'!$G:$G,Summary!$L20) -> 2097640 | P20: =N20-O20 -> -97640 | Q20: =1-IFERROR(O20/N20,"") -> -0.04882
C21: 예적금/금융자산 | D21: =D16-D18-D19-D20 -> 34340667 | E21: =E26-D26 -> 14393470 | F21: =IFERROR(E21/D21,0) -> 0.41913775 | G21: =E21-D21 -> -19947197 | L21: 취미 | M21: 헬스/수영 등 | N21: 1000000 | O21: =SUMIFS('지출내역'!$I:$I,'지출내역'!$F:$F,"고정비",'지출내역'!$G:$G,Summary!$L21) -> 1362198.2 | P21: =N21-O21 -> -362198.2 | Q21: =1-IFERROR(O21/N21,"") -> -0.3621982
C22: 카드결제예정액 | E22: =SUM(G36:G39)*-1 -> -2921275 | L22: 비품 및 수선유지비 | N22: 3500000 | O22: =SUMIFS('지출내역'!$I:$I,'지출내역'!$F:$F,"고정비",'지출내역'!$G:$G,Summary!$L22) -> 3563568 | P22: =N22-O22 -> -63568 | Q22: =1-IFERROR(O22/N22,"") -> -0.018162286
L23: 주택담보대출 이자 | N23: 5000000 | O23: =SUMIFS('지출내역'!$I:$I,'지출내역'!$F:$F,"고정비",'지출내역'!$G:$G,Summary!$L23) -> 4197055.3 | P23: =N23-O23 -> 802944.66 | Q23: =1-IFERROR(O23/N23,"") -> 0.16058893
D24: 예적금/금융자산 | L24: 의료/건강 | N24: 4000000 | O24: =SUMIFS('지출내역'!$I:$I,'지출내역'!$F:$F,"고정비",'지출내역'!$G:$G,Summary!$L24) -> 1423081 | P24: =N24-O24 -> 2576919 | Q24: =1-IFERROR(O24/N24,"") -> 0.64422975
D25: 기초 | E25: 기말 | L25: 예비비 | N25: 1500000 | O25: =SUMIFS('지출내역'!$I:$I,'지출내역'!$F:$F,"고정비",'지출내역'!$G:$G,Summary!$L25) -> 964090 | P25: =N25-O25 -> 535910 | Q25: =1-IFERROR(O25/N25,"") -> 0.35727333
D26: 23067103 | E26: =SUM(G26:G34) -> 37460573 | F26: Laki KB | G26: 8047004 | L26: 교육비 | N26: 4000000 | O26: =SUMIFS('지출내역'!$I:$I,'지출내역'!$F:$F,"고정비",'지출내역'!$G:$G,Summary!$L26) -> 3674260 | P26: =N26-O26 -> 325740 | Q26: =1-IFERROR(O26/N26,"") -> 0.081435
F27: Piece KB | G27: =3428712 -> 3428712 | L27: 브랜디식대 | M27: 월 18만원 | N27: =180000*2 -> 360000 | O27: =SUMIFS('지출내역'!$I:$I,'지출내역'!$F:$F,"고정비",'지출내역'!$G:$G,Summary!$L27) -> 315600 | P27: =N27-O27 -> 44400 | Q27: =1-IFERROR(O27/N27,"") -> 0.12333333
F28: Piece SC | G28: 9009653
F29: Laki KB 외 | G29: 10082040
F30: Laki 주식계좌 | G30: 6095164
K31: #2. 변동비 계획 | N31: =SUM(N33:N40) -> 19646000 | O31: =SUM(O33:O40) -> 19103416 | P31: =SUM(P33:P40) -> 542584 | Q31: 잔여금액 | R31: =P31/N31 -> 0.027618039
F32: Laki 제로페이 | G32: 402900 | L32: 변동비 구분 | N32: 연간계획 | O32: 누적 사용금액 | P32: 잔액 | Q32: 잔여기간 | R32: =(DATE(2022,12,31)-DATE(YEAR(NOW()),MONTH(NOW()),DAY(NOW())))/365 -> -3.1369863
F33: Piece 제로페이 | G33: 395100 | L33: 기타구매 | N33: 5000000 | O33: =SUMIFS('지출내역'!$I:$I,'지출내역'!$F:$F,"변동비",'지출내역'!$G:$G,Summary!$L33) -> 4730317 | P33: =N33-O33 -> 269683 | Q33: =1-IFERROR(O33/N33,"") -> 0.0539366
D34: 2022.12.31. | L34: 담배 | N34: =4500*4*52 -> 936000 | O34: =SUMIFS('지출내역'!$I:$I,'지출내역'!$F:$F,"변동비",'지출내역'!$G:$G,Summary!$L34) -> 908735 | P34: =N34-O34 -> 27265 | Q34: =1-IFERROR(O34/N34,"") -> 0.029129274
L35: 모임비 | M35: 연간 150만원예상 | N35: 1000000 | O35: =SUMIFS('지출내역'!$I:$I,'지출내역'!$F:$F,"변동비",'지출내역'!$G:$G,Summary!$L35) -> 881470 | P35: =N35-O35 -> 118530 | Q35: =1-IFERROR(O35/N35,"") -> 0.11853
D36: 카드결제예정액 | F36: piece KB | G36: 684148 | L36: 식비 | M36: 연간 650만원예상 | N36: 6500000 | O36: =SUMIFS('지출내역'!$I:$I,'지출내역'!$F:$F,"변동비",'지출내역'!$G:$G,Summary!$L36) -> 6401752 | P36: =N36-O36 -> 98248 | Q36: =1-IFERROR(O36/N36,"") -> 0.015115077
D37: 기초 | E37: 기말 | F37: laki-신한 | G37: 329381 | L37: 외식비 | M37: 연간 300만원예상 | N37: 3500000 | O37: =SUMIFS('지출내역'!$I:$I,'지출내역'!$F:$F,"변동비",'지출내역'!$G:$G,Summary!$L37) -> 3873179 | P37: =N37-O37 -> -373179 | Q37: =1-IFERROR(O37/N37,"") -> -0.10662257
E38: =SUM(G36:G39) -> 2921275 | F38: laki 현대 | G38: 45652 | L38: 의류 | N38: 2000000 | O38: =SUMIFS('지출내역'!$I:$I,'지출내역'!$F:$F,"변동비",'지출내역'!$G:$G,Summary!$L38) -> 1658308 | P38: =N38-O38 -> 341692 | Q38: =1-IFERROR(O38/N38,"") -> 0.170846
D39: 2022.12.31. | F39: laki KB | G39: 1862094 | L39: 출근식대 | M39: 주 평균 9000원 x 5일 x 5주 | N39: 200000 | O39: =SUMIFS('지출내역'!$I:$I,'지출내역'!$F:$F,"변동비",'지출내역'!$G:$G,Summary!$L39) -> 68000 | P39: =N39-O39 -> 132000 | Q39: =1-IFERROR(O39/N39,"") -> 0.66
L40: 커피 | M40: 원두 월 3만원 + a | N40: =12*30000+150000 -> 510000 | O40: =SUMIFS('지출내역'!$I:$I,'지출내역'!$F:$F,"변동비",'지출내역'!$G:$G,Summary!$L40) -> 581655 | P40: =N40-O40 -> -71655 | Q40: =1-IFERROR(O40/N40,"") -> -0.1405
B42: 4. 미집계금액
C43: 구분 | E43: 금액 | H43: 비고 | L43: 주 기준금액 | M43: 377000 | N43: =N31/52 -> 377807.69 | P43: =P31 -> 542584
...

Sheet 지출내역
B1: 날짜 | C1: 월 | D1: 요일 | E1: 주 | F1: 분류 | G1: 내역 | H1: 결제수단 | I1: 금액 | J1: 작성자 | K1: 비고
B2: 44651 | C2: =DATE(YEAR(B2),MONTH(B2),1) -> 44621 | D2: =IF(B2="","",B2) -> 44651 | E2: =WEEKNUM(B2) -> 14 | F2: 대출상환 | G2: 주택담보대출 원금 | H2: 현금 | I2: 6200000 | J2: p | K2: 중도상환
B3: 44578 | C3: =DATE(YEAR(B3),MONTH(B3),1) -> 44562 | D3: =IF(B3="","",B3) -> 44578 | E3: =WEEKNUM(B3) -> 4 | F3: 대출상환 | G3: 주택담보대출 원금 | H3: 현금 | I3: 3700000 | J3: p
B4: 44732 | C4: =DATE(YEAR(B4),MONTH(B4),1) -> 44713 | D4: =IF(B4="","",B4) -> 44732 | E4: =WEEKNUM(B4) -> 26 | F4: 대출상환 | G4: 주택담보대출 원금 | H4: 현금 | I4: 3000000 | J4: p
B5: 44715 | C5: =DATE(YEAR(B5),MONTH(B5),1) -> 44713 | D5: =IF(B5="","",B5) -> 44715 | E5: =WEEKNUM(B5) -> 23 | F5: 대출상환 | G5: 주택담보대출 원금 | H5: 현금 | I5: 2800000 | J5: p
B6: 44744 | C6: =DATE(YEAR(B6),MONTH(B6),1) -> 44743 | D6: =IF(B6="","",B6) -> 44744 | E6: =WEEKNUM(B6) -> 27 | F6: 대출상환 | G6: 주택담보대출 원금 | H6: 현금 | I6: 2400000 | J6: p
B7: 44682 | C7: =DATE(YEAR(B7),MONTH(B7),1) -> 44682 | D7: =IF(B7="","",B7) -> 44682 | E7: =WEEKNUM(B7) -> 19 | F7: 대출상환 | G7: 주택담보대출 원금 | H7: 현금 | I7: 2350000 | J7: p
B8: 44620 | C8: =DATE(YEAR(B8),MONTH(B8),1) -> 44593 | D8: =IF(B8="","",B8) -> 44620 | E8: =WEEKNUM(B8) -> 10 | F8: 대출상환 | G8: 주택담보대출 원금 | H8: 현금 | I8: 2200000 | J8: p
B9: 44614 | C9: =DATE(YEAR(B9),MONTH(B9),1) -> 44593 | D9: =IF(B9="","",B9) -> 44614 | E9: =WEEKNUM(B9) -> 9 | F9: 고정비 | G9: 교육비 | H9: 카드 | I9: 2040000 | J9: L | K9: 대학원 등록금
B10: 44562 | C10: =DATE(YEAR(B10),MONTH(B10),1) -> 44562 | D10: =IF(B10="","",B10) -> 44562 | E10: =WEEKNUM(B10) -> 1 | F10: 대출상환 | G10: 주택담보대출 원금 | H10: 현금 | I10: 2000000 | J10: p | K10: 중도상환
B11: 44589 | C11: =DATE(YEAR(B11),MONTH(B11),1) -> 44562 | D11: =IF(B11="","",B11) -> 44589 | E11: =WEEKNUM(B11) -> 5 | F11: 대출상환 | G11: 주택담보대출 원금 | H11: 현금 | I11: 1800000 | J11: p
B12: 44795 | C12: =DATE(YEAR(B12),MONTH(B12),1) -> 44774 | D12: =IF(B12="","",B12) -> 44795 | E12: =WEEKNUM(B12) -> 35 | F12: 대출상환 | G12: 주택담보대출 원금 | H12: 현금 | I12: 1750014 | J12: p
B13: 44818 | C13: =DATE(YEAR(B13),MONTH(B13),1) -> 44805 | D13: =IF(B13="","",B13) -> 44818 | E13: =WEEKNUM(B13) -> 38 | F13: 고정비 | G13: 교육비 | H13: 카드 | I13: 1580000 | J13: L | K13: 대학원 등록금
B14: 44666 | C14: =DATE(YEAR(B14),MONTH(B14),1) -> 44652 | D14: =IF(B14="","",B14) -> 44666 | E14: =WEEKNUM(B14) -> 16 | F14: 대출상환 | G14: 주택담보대출 원금 | H14: 현금 | I14: 1500000 | J14: p
B15: 44843 | C15: =DATE(YEAR(B15),MONTH(B15),1) -> 44835 | D15: =IF(B15="","",B15) -> 44843 | E15: =WEEKNUM(B15) -> 42 | F15: 대출상환 | G15: 주택담보대출 원금 | H15: 현금 | I15: 1480000 | J15: p
B16: 44689 | C16: =DATE(YEAR(B16),MONTH(B16),1) -> 44682 | D16: =IF(B16="","",B16) -> 44689 | E16: =WEEKNUM(B16) -> 20 | F16: 대출상환 | G16: 주택담보대출 원금 | H16: 현금 | I16: 1200000 | J16: p
B17: 44751 | C17: =DATE(YEAR(B17),MONTH(B17),1) -> 44743 | D17: =IF(B17="","",B17) -> 44751 | E17: =WEEKNUM(B17) -> 28 | F17: 고정비 | G17: 비품 및 수선유지비 | H17: 카드 | I17: 1139720 | J17: L | K17: 롯데온: 맥북에어M1
B18: 44615 | C18: =DATE(YEAR(B18),MONTH(B18),1) -> 44593 | D18: =IF(B18="","",B18) -> 44615 | E18: =WEEKNUM(B18) -> 9 | F18: 대출상환 | G18: 주택담보대출 원금 | H18: 현금 | I18: 1100000 | J18: p
B19: 44650 | C19: =DATE(YEAR(B19),MONTH(B19),1) -> 44621 | D19: =IF(B19="","",B19) -> 44650 | E19: =WEEKNUM(B19) -> 14 | F19: 대출상환 | G19: 주택담보대출 원금 | H19: 현금 | I19: 1100000 | J19: p | K19: 중도상환
B20: 44748 | C20: =DATE(YEAR(B20),MONTH(B20),1) -> 44743 | D20: =IF(B20="","",B20) -> 44748 | E20: =WEEKNUM(B20) -> 28 | F20: 여행공연비 | G20: 해외여행 | H20: 카드 | I20: 1080800 | J20: L | K20: 에어서울 : 서울-나트랑 왕복 2인
B21: 44764 | C21: =DATE(YEAR(B21),MONTH(B21),1) -> 44743 | D21: =IF(B21="","",B21) -> 44764 | E21: =WEEKNUM(B21) -> 30 | F21: 대출상환 | G21: 주택담보대출 원금 | H21: 현금 | I21: 1007589 | J21: p
B22: 44666 | C22: =DATE(YEAR(B22),MONTH(B22),1) -> 44652 | D22: =IF(B22="","",B22) -> 44666 | E22: =WEEKNUM(B22) -> 16 | F22: 대출상환 | G22: 주택담보대출 원금 | H22: 현금 | I22: 1000000 | J22: p
B23: 44687 | C23: =DATE(YEAR(B23),MONTH(B23),1) -> 44682 | D23: =IF(B23="","",B23) -> 44687 | E23: =WEEKNUM(B23) -> 19 | F23: 대출상환 | G23: 주택담보대출 원금 | H23: 현금 | I23: 1000000 | J23: p
B24: 44702 | C24: =DATE(YEAR(B24),MONTH(B24),1) -> 44682 | D24: =IF(B24="","",B24) -> 44702 | E24: =WEEKNUM(B24) -> 21 | F24: 대출상환 | G24: 주택담보대출 원금 | H24: 현금 | I24: 1000000 | J24: p
B25: 44773 | C25: =DATE(YEAR(B25),MONTH(B25),1) -> 44743 | D25: =IF(B25="","",B25) -> 44773 | E25: =WEEKNUM(B25) -> 32 | F25: 대출상환 | G25: 주택담보대출 원금 | H25: 현금 | I25: 1000000 | J25: p
B26: 44775 | C26: =DATE(YEAR(B26),MONTH(B26),1) -> 44774 | D26: =IF(B26="","",B26) -> 44775 | E26: =WEEKNUM(B26) -> 32 | F26: 대출상환 | G26: 주택담보대출 원금 | H26: 현금 | I26: 1000000 | J26: p
B27: 44723 | C27: =DATE(YEAR(B27),MONTH(B27),1) -> 44713 | D27: =IF(B27="","",B27) -> 44723 | E27: =WEEKNUM(B27) -> 24 | F27: 대출상환 | G27: 주택담보대출 원금 | H27: 현금 | I27: 900000 | J27: p
B28: 44806 | C28: =DATE(YEAR(B28),MONTH(B28),1) -> 44805 | D28: =IF(B28="","",B28) -> 44806 | E28: =WEEKNUM(B28) -> 36 | F28: 여행공연비 | G28: 해외여행 | H28: 카드 | I28: 811500 | J28: L | K28: 제주항공: 인천-보홀 왕복 2인
B29: 44764 | C29: =DATE(YEAR(B29),MONTH(B29),1) -> 44743 | D29: =IF(B29="","",B29) -> 44764 | E29: =WEEKNUM(B29) -> 30 | F29: 대출상환 | G29: 주택담보대출 원금 | H29: 현금 | I29: 740000 | J29: p
B30: 44873 | C30: =DATE(YEAR(B30),MONTH(B30),1) -> 44866 | D30: =IF(B30="","",B30) -> 44873 | E30: =WEEKNUM(B30) -> 46 | F30: 고정비 | G30: 취미 | H30: 카드 | I30: 740000 | J30: L | K30: 네이버: 고고다이브 프리다이빙 초급강습
B31: 44748 | C31: =DATE(YEAR(B31),MONTH(B31),1) -> 44743 | D31: =IF(B31="","",B31) -> 44748 | E31: =WEEKNUM(B31) -> 28 | F31: 여행공연비 | G31: 해외여행 | H31: 카드 | I31: 705124 | J31: p | K31: 트리플 : 나트랑 아미아나 리조트 3박
B32: 44809 | C32: =DATE(YEAR(B32),MONTH(B32),1) -> 44805 | D32: =IF(B32="","",B32) -> 44809 | E32: =WEEKNUM(B32) -> 37 | F32: 대출상환 | G32: 주택담보대출 원금 | H32: 현금 | I32: =247074+452926 -> 700000 | J32: p
B33: 44916 | C33: =DATE(YEAR(B33),MONTH(B33),1) -> 44896 | D33: =IF(B33="","",B33) -> 44916 | E33: =WEEKNUM(B33) -> 52 | F33: 여행공연비 | G33: 해외여행 | H33: 카드 | I33: 626727 | J33: L | K33: 아고다: 사우스팜 디럭스풀뷰(2/1/~2/4)
B34: 44686 | C34: =DATE(YEAR(B34),MONTH(B34),1) -> 44682 | D34: =IF(B34="","",B34) -> 44686 | E34: =WEEKNUM(B34) -> 19 | F34: 고정비 | G34: 문경 | H34: 현금 | I34: 600000 | J34: L | K34: 양가 어버이날 용돈
B35: 44813 | C35: =DATE(YEAR(B35),MONTH(B35),1) -> 44805 | D35: =IF(B35="","",B35) -> 44813 | E35: =WEEKNUM(B35) -> 37 | F35: 고정비 | G35: 문경 | H35: 현금 | I35: 600000 | J35: L | K35: 양가용돈
B36: 44836 | C36: =DATE(YEAR(B36),MONTH(B36),1) -> 44835 | D36: =IF(B36="","",B36) -> 44836 | E36: =WEEKNUM(B36) -> 41 | F36: 변동비 | G36: 기타구매 | H36: 카드 | I36: 596750 | J36: p | K36: 고프로 gopro.com GoPro Hero 11 Black Bundle : $411.70
B37: 44772 | C37: =DATE(YEAR(B37),MONTH(B37),1) -> 44743 | D37: =IF(B37="","",B37) -> 44772 | E37: =WEEKNUM(B37) -> 31 | F37: 여행공연비 | G37: 해외여행 | H37: 현금 | I37: =791764-290000 -> 501764 | J37: L | K37: $600 환전 (VND 5260k 29만원에 당근거래)
B38: 44570 | C38: =DATE(YEAR(B38),MONTH(B38),1) -> 44562 | D38: =IF(B38="","",B38) -> 44570 | E38: =WEEKNUM(B38) -> 3 | F38: 고정비 | G38: 예비비 | H38: 카드 | I38: 484300 | J38: L | K38: 롯데홈쇼핑: 애플워치7 41mm
B39: 44570 | C39: =DATE(YEAR(B39),MONTH(B39),1) -> 44562 | D39: =IF(B39="","",B39) -> 44570 | E39: =WEEKNUM(B39) -> 3 | F39: 고정비 | G39: 예비비 | H39: 카드 | I39: =528220-48430 -> 479790 | J39: L | K39: 하이마트: 애플워치7 45mm(L포인트 48430 사용)
B40: 44899 | C40: =DATE(YEAR(B40),MONTH(B40),1) -> 44896 | D40: =IF(B40="","",B40) -> 44899 | E40: =WEEKNUM(B40) -> 50 | F40: 고정비 | G40: 보험 | H40: 카드 | I40: 459580 | J40: p | K40: DB 다이렉트 자동차보험
...

Sheet 현금입금
B1: 날짜 | C1: 월 | D1: 요일 | E1: 주 | F1: 구분 | G1: 내역 | H1: 금액 | I1: 작성자 | J1: 비고
B2: 44566 | C2: =DATE(YEAR(B2),MONTH(B2),1) -> 44562 | D2: =IF(B2="","",B2) -> 44566 | E2: =WEEKNUM(B2) -> 2 | F2: 입금 | G2: 기프티스타 | H2: 5790 | I2: L | J2: 기프티콘 판매
B3: 44571 | C3: =DATE(YEAR(B3),MONTH(B3),1) -> 44562 | D3: =IF(B3="","",B3) -> 44571 | E3: =WEEKNUM(B3) -> 3 | F3: 입금 | G3: 기프티스타 | H3: 8750 | I3: L | J3: 기프티콘 판매
B4: 44578 | C4: =DATE(YEAR(B4),MONTH(B4),1) -> 44562 | D4: =IF(B4="","",B4) -> 44578 | E4: =WEEKNUM(B4) -> 4 | F4: 입금 | G4: 1월 급여 | H4: 6941660 | I4: L | J4: 1월 정근수당, 명절 수당 포함
B5: 44580 | C5: =DATE(YEAR(B5),MONTH(B5),1) -> 44562 | D5: =IF(B5="","",B5) -> 44580 | E5: =WEEKNUM(B5) -> 4 | F5: 입금 | G5: 적금 이자 | H5: =1200+4750 -> 5950 | I5: L | J5: 적금 만기 이자
B6: 44585 | C6: =DATE(YEAR(B6),MONTH(B6),1) -> 44562 | D6: =IF(B6="","",B6) -> 44585 | E6: =WEEKNUM(B6) -> 5 | F6: 입금 | G6: 1월 식대 | H6: 180400 | I6: p
B7: 44585 | C7: =DATE(YEAR(B7),MONTH(B7),1) -> 44562 | D7: =IF(B7="","",B7) -> 44585 | E7: =WEEKNUM(B7) -> 5 | F7: 입금 | G7: 기프티스타 | H7: 7690 | I7: L | J7: 기프티콘 판매
B8: 44586 | C8: =DATE(YEAR(B8),MONTH(B8),1) -> 44562 | D8: =IF(B8="","",B8) -> 44586 | E8: =WEEKNUM(B8) -> 5 | F8: 입금 | G8: 국제과학영재학회 | H8: 547200 | I8: L | J8: 문제출제 수당
B9: 44589 | C9: =DATE(YEAR(B9),MONTH(B9),1) -> 44562 | D9: =IF(B9="","",B9) -> 44589 | E9: =WEEKNUM(B9) -> 5 | F9: 입금 | G9: 브랜디 처조부상 조의금 | H9: 100000 | I9: p
B10: 44589 | C10: =DATE(YEAR(B10),MONTH(B10),1) -> 44562 | D10: =IF(B10="","",B10) -> 44589 | E10: =WEEKNUM(B10) -> 5 | F10: 입금 | G10: 1월 급여 | H10: 3693100 | I10: p
B11: 44593 | C11: =DATE(YEAR(B11),MONTH(B11),1) -> 44593 | D11: =IF(B11="","",B11) -> 44593 | E11: =WEEKNUM(B11) -> 6 | F11: 입금 | G11: 세뱃돈 | H11: 260000 | I11: L
B12: 44595 | C12: =DATE(YEAR(B12),MONTH(B12),1) -> 44593 | D12: =IF(B12="","",B12) -> 44595 | E12: =WEEKNUM(B12) -> 6 | F12: 입금 | G12: 기프티스타 | H12: 5630 | I12: L | J12: 기프티콘 판매
B13: 44599 | C13: =DATE(YEAR(B13),MONTH(B13),1) -> 44593 | D13: =IF(B13="","",B13) -> 44599 | E13: =WEEKNUM(B13) -> 7 | F13: 입금 | G13: 월드와이드메모리 | H13: 239000 | I13: p | J13: i7-6770K,i5-3570,DDR3 메모리 판매
B14: 44602 | C14: =DATE(YEAR(B14),MONTH(B14),1) -> 44593 | D14: =IF(B14="","",B14) -> 44602 | E14: =WEEKNUM(B14) -> 7 | F14: 입금 | G14: 파인테크캐시백 | H14: 2244 | I14: p
B15: 44602 | C15: =DATE(YEAR(B15),MONTH(B15),1) -> 44593 | D15: =IF(B15="","",B15) -> 44602 | E15: =WEEKNUM(B15) -> 7 | F15: 입금 | G15: 파인테크캐시백 | H15: 10000 | I15: L
B16: 44604 | C16: =DATE(YEAR(B16),MONTH(B16),1) -> 44593 | D16: =IF(B16="","",B16) -> 44604 | E16: =WEEKNUM(B16) -> 7 | F16: 입금 | G16: 예금 이자 | H16: 2330 | I16: L
B17: 44609 | C17: =DATE(YEAR(B17),MONTH(B17),1) -> 44593 | D17: =IF(B17="","",B17) -> 44609 | E17: =WEEKNUM(B17) -> 8 | F17: 입금 | G17: 2월 급여 | H17: 3533110 | I17: L | J17: 연말정산 환급금 1/2 포함
B18: 44614 | C18: =DATE(YEAR(B18),MONTH(B18),1) -> 44593 | D18: =IF(B18="","",B18) -> 44614 | E18: =WEEKNUM(B18) -> 9 | F18: 입금 | G18: 서울교대 영재원 | H18: 500000 | I18: L | J18: 영재원 멘토링
B19: 44615 | C19: =DATE(YEAR(B19),MONTH(B19),1) -> 44593 | D19: =IF(B19="","",B19) -> 44615 | E19: =WEEKNUM(B19) -> 9 | F19: 입금 | G19: 2월 식대 | H19: 180000 | I19: p
B20: 44617 | C20: =DATE(YEAR(B20),MONTH(B20),1) -> 44593 | D20: =IF(B20="","",B20) -> 44617 | E20: =WEEKNUM(B20) -> 9 | F20: 입금 | G20: 현대카드 | H20: 30000 | I20: L | J20: 연회비 캐시백
B21: 44620 | C21: =DATE(YEAR(B21),MONTH(B21),1) -> 44593 | D21: =IF(B21="","",B21) -> 44620 | E21: =WEEKNUM(B21) -> 10 | F21: 입금 | G21: 2월 급여 | H21: 4515720 | I21: p | J21: 연말정산 환급금(822,646원) 포함
B22: 44620 | C22: =DATE(YEAR(B22),MONTH(B22),1) -> 44593 | D22: =IF(B22="","",B22) -> 44620 | E22: =WEEKNUM(B22) -> 10 | F22: 입금 | G22: 신한카드 | H22: 54340 | I22: L | J22: 포인트 환급
B23: 44620 | C23: =DATE(YEAR(B23),MONTH(B23),1) -> 44593 | D23: =IF(B23="","",B23) -> 44620 | E23: =WEEKNUM(B23) -> 10 | F23: 입금 | G23: KB | H23: 27987 | I23: L | J23: 포인트리 환급
B24: 44622 | C24: =DATE(YEAR(B24),MONTH(B24),1) -> 44621 | D24: =IF(B24="","",B24) -> 44622 | E24: =WEEKNUM(B24) -> 10 | F24: 입금 | G24: 신한카드 | H24: 5000 | I24: L | J24: 마이샵 캐시백
B25: 44623 | C25: =DATE(YEAR(B25),MONTH(B25),1) -> 44621 | D25: =IF(B25="","",B25) -> 44623 | E25: =WEEKNUM(B25) -> 10 | F25: 입금 | G25: 기프티스타 | H25: 6390 | I25: L | J25: 기프티콘 판매
B26: 44627 | C26: =DATE(YEAR(B26),MONTH(B26),1) -> 44621 | D26: =IF(B26="","",B26) -> 44627 | E26: =WEEKNUM(B26) -> 11 | F26: 입금 | G26: 카카오 선물 환불 | H26: 32940 | I26: p
B27: 44630 | C27: =DATE(YEAR(B27),MONTH(B27),1) -> 44621 | D27: =IF(B27="","",B27) -> 44630 | E27: =WEEKNUM(B27) -> 11 | F27: 입금 | G27: KB | H27: 6742 | I27: p | J27: 파인테크 캐시백
B28: 44630 | C28: =DATE(YEAR(B28),MONTH(B28),1) -> 44621 | D28: =IF(B28="","",B28) -> 44630 | E28: =WEEKNUM(B28) -> 11 | F28: 입금 | G28: 3월 식대 | H28: 71500 | I28: p | J28: 개인카드 결제건
B29: 44637 | C29: =DATE(YEAR(B29),MONTH(B29),1) -> 44621 | D29: =IF(B29="","",B29) -> 44637 | E29: =WEEKNUM(B29) -> 12 | F29: 입금 | G29: 3월 급여 | H29: 3493590 | I29: L | J29: 연말정산 환급금 1/2 포함
B30: 44639 | C30: =DATE(YEAR(B30),MONTH(B30),1) -> 44621 | D30: =IF(B30="","",B30) -> 44639 | E30: =WEEKNUM(B30) -> 12 | F30: 입금 | G30: KB | H30: 26934 | I30: p | J30: 포인트리 환급
B31: 44643 | C31: =DATE(YEAR(B31),MONTH(B31),1) -> 44621 | D31: =IF(B31="","",B31) -> 44643 | E31: =WEEKNUM(B31) -> 13 | F31: 입금 | G31: 3월 식대 | H31: 62400 | I31: p | J31: 하나카드 결제건
B32: 44648 | C32: =DATE(YEAR(B32),MONTH(B32),1) -> 44621 | D32: =IF(B32="","",B32) -> 44648 | E32: =WEEKNUM(B32) -> 14 | F32: 입금 | G32: 기프티스타 | H32: 7650 | I32: L | J32: 기프티콘 판매
B33: 44649 | C33: =DATE(YEAR(B33),MONTH(B33),1) -> 44621 | D33: =IF(B33="","",B33) -> 44649 | E33: =WEEKNUM(B33) -> 14 | F33: 입금 | G33: 신한카드 | H33: 10000 | I33: L | J33: 신한카드 캐시백
B34: 44651 | C34: =DATE(YEAR(B34),MONTH(B34),1) -> 44621 | D34: =IF(B34="","",B34) -> 44651 | E34: =WEEKNUM(B34) -> 14 | F34: 입금 | G34: 3월 급여 | H34: 4250760 | I34: p
B35: 44651 | C35: =DATE(YEAR(B35),MONTH(B35),1) -> 44621 | D35: =IF(B35="","",B35) -> 44651 | E35: =WEEKNUM(B35) -> 14 | F35: 입금 | G35: 성과상여금 | H35: 4817050 | I35: L
B36: 44651 | C36: =DATE(YEAR(B36),MONTH(B36),1) -> 44621 | D36: =IF(B36="","",B36) -> 44651 | E36: =WEEKNUM(B36) -> 14 | F36: 입금 | G36: 서울교대 영재원 | H36: 592800 | I36: L | J36: 탐구과제 지도비
B37: 44652 | C37: =DATE(YEAR(B37),MONTH(B37),1) -> 44652 | D37: =IF(B37="","",B37) -> 44652 | E37: =WEEKNUM(B37) -> 14 | F37: 입금 | G37: 기프티스타 | H37: 9150 | I37: L | J37: 기프티콘 판매
B38: 44652 | C38: =DATE(YEAR(B38),MONTH(B38),1) -> 44652 | D38: =IF(B38="","",B38) -> 44652 | E38: =WEEKNUM(B38) -> 14 | F38: 입금 | G38: 맞춤형복지 | H38: 178460 | I38: L | J38: 복지포인트 환급
B39: 44659 | C39: =DATE(YEAR(B39),MONTH(B39),1) -> 44652 | D39: =IF(B39="","",B39) -> 44659 | E39: =WEEKNUM(B39) -> 15 | F39: 입금 | G39: 파인테크캐시백 | H39: 10000 | I39: L
B40: 44666 | C40: =DATE(YEAR(B40),MONTH(B40),1) -> 44652 | D40: =IF(B40="","",B40) -> 44666 | E40: =WEEKNUM(B40) -> 16 | F40: 입금 | G40: 4월 급여 | H40: 3175740 | I40: L
...

Sheet 집계

Sheet 변동비 집계
E3: 주차 | F3: 기준금액 | G3: 차액 | H3: 누적사용금액 | I3: 누적기준금액 | J3: 누적차액 | L3: 총 주수 | M3: =COUNT(B:B) -> 53
E4: 1 | F4: =IF(AND(B4<>"총합계",B4<>""),변동비기준,0) -> #NAME? | G4: =IF(F4<>"",F4-C4,"") -> #NAME? | H4: =C4 -> 139688 | I4: =F4 -> #NAME? | J4: =I4-H4 -> #NAME? | L4: 누적 차액 | M4: =SUM(G:G) -> #NAME?
E5: =E4+1 -> 2 | F5: =IF(AND(B5<>"총합계",B5<>""),변동비기준,0) -> #NAME? | G5: =IF(F5<>"",F5-C5,"") -> #NAME? | H5: =H4+C5 -> 549657 | I5: =I4+F5 -> #NAME? | J5: =I5-H5 -> #NAME? | L5: =IF(M4>0,"GOOD!!","BAD!!") -> #NAME?
E6: =E5+1 -> 3 | F6: =IF(AND(B6<>"총합계",B6<>""),변동비기준,0) -> #NAME? | G6: =IF(F6<>"",F6-C6,"") -> #NAME? | H6: =H5+C6 -> 966349 | I6: =I5+F6 -> #NAME? | J6: =I6-H6 -> #NAME?
E7: =E6+1 -> 4 | F7: =IF(AND(B7<>"총합계",B7<>""),변동비기준,0) -> #NAME? | G7: =IF(F7<>"",F7-C7,"") -> #NAME? | H7: =H6+C7 -> 1138835 | I7: =I6+F7 -> #NAME? | J7: =I7-H7 -> #NAME?
E8: =E7+1 -> 5 | F8: =IF(AND(B8<>"총합계",B8<>""),변동비기준,0) -> #NAME? | G8: =IF(F8<>"",F8-C8,"") -> #NAME? | H8: =H7+C8 -> 1220368 | I8: =I7+F8 -> #NAME? | J8: =I8-H8 -> #NAME?
E9: =E8+1 -> 6 | F9: =IF(AND(B9<>"총합계",B9<>""),변동비기준,0) -> #NAME? | G9: =IF(F9<>"",F9-C9,"") -> #NAME? | H9: =H8+C9 -> 1472063 | I9: =I8+F9 -> #NAME? | J9: =I9-H9 -> #NAME?
E10: =E9+1 -> 7 | F10: =IF(AND(B10<>"총합계",B10<>""),변동비기준,0) -> #NAME? | G10: =IF(F10<>"",F10-C10,"") -> #NAME? | H10: =H9+C10 -> 1786935 | I10: =I9+F10 -> #NAME? | J10: =I10-H10 -> #NAME?
E11: =E10+1 -> 8 | F11: =IF(AND(B11<>"총합계",B11<>""),변동비기준,0) -> #NAME? | G11: =IF(F11<>"",F11-C11,"") -> #NAME? | H11: =H10+C11 -> 2325779 | I11: =I10+F11 -> #NAME? | J11: =I11-H11 -> #NAME?
E12: =E11+1 -> 9 | F12: =IF(AND(B12<>"총합계",B12<>""),변동비기준,0) -> #NAME? | G12: =IF(F12<>"",F12-C12,"") -> #NAME? | H12: =H11+C12 -> 2495392 | I12: =I11+F12 -> #NAME? | J12: =I12-H12 -> #NAME?
E13: =E12+1 -> 10 | F13: =IF(AND(B13<>"총합계",B13<>""),변동비기준,0) -> #NAME? | G13: =IF(F13<>"",F13-C13,"") -> #NAME? | H13: =H12+C13 -> 3014673 | I13: =I12+F13 -> #NAME? | J13: =I13-H13 -> #NAME?
E14: =E13+1 -> 11 | F14: =IF(AND(B14<>"총합계",B14<>""),변동비기준,0) -> #NAME? | G14: =IF(F14<>"",F14-C14,"") -> #NAME? | H14: =H13+C14 -> 3402724 | I14: =I13+F14 -> #NAME? | J14: =I14-H14 -> #NAME?
E15: =E14+1 -> 12 | F15: =IF(AND(B15<>"총합계",B15<>""),변동비기준,0) -> #NAME? | G15: =IF(F15<>"",F15-C15,"") -> #NAME? | H15: =H14+C15 -> 3803024 | I15: =I14+F15 -> #NAME? | J15: =I15-H15 -> #NAME?
E16: =E15+1 -> 13 | F16: =IF(AND(B16<>"총합계",B16<>""),변동비기준,0) -> #NAME? | G16: =IF(F16<>"",F16-C16,"") -> #NAME? | H16: =H15+C16 -> 3986889 | I16: =I15+F16 -> #NAME? | J16: =I16-H16 -> #NAME?
E17: =E16+1 -> 14 | F17: =IF(AND(B17<>"총합계",B17<>""),변동비기준,0) -> #NAME? | G17: =IF(F17<>"",F17-C17,"") -> #NAME? | H17: =H16+C17 -> 4581455 | I17: =I16+F17 -> #NAME? | J17: =I17-H17 -> #NAME?
... E56: =E55+1 -> 53 | F56: =IF(AND(B56<>"총합계",B56<>""),변동비기준,0) -> #NAME? | G56: =IF(F56<>"",F56-C56,"") -> #NAME? | H56: =H55+C56 -> 19103416 | I56: =I55+F56 -> #NAME? | J56: =I56-H56 -> #NAME?

Sheet 주택담보대출
B1: [최초 대출내역] | L1: [현재 대출내역] | N1: 43617 | O1: 상환률 | R1: 연평균 상환원금 | S1: =S2/INT(NOW()-N1)*365 -> 22414456
C2: 대출액 | E2: 260000000 | F2: =E2 -> 260000000 | M2: 대출액 | N2: 260000000 | O2: =S2/N2 -> 0.57961089 | R2: 총 상환원금 | S2: =SUMIFS($O$9:$O$368,$N$9:$N$368,"<="&DATE(YEAR(NOW()),MONTH(NOW()),1)) -> 1.5069883e+08
C3: 이율(%) | E3: 0.0303 | M3: 이율(%) | N3: 0.0303 | R3: 총 지급이자 | S3: =SUMIFS($P$9:$P$368,$N$9:$N$368,"<="&DATE(YEAR(NOW()),MONTH(NOW()),1)) -> 33680068
C4: 상환기간(년) | E4: 30 | F4: =E4*12 -> 360 | M4: 상환기간(년) | N4: 30 | R4: 30년간 대출이자 감소 | S4: =E5-N5 -> 59341572
C5: 총 대출이자 | E5: =G9*F4-E2 -> 1.3613741e+08 | M5: 총 대출이자 | N5: =SUM(P9:P368) -> 76795839 | R5: 월 상환액 감소 | S5: =E6-N6 -> 554084.41
C6: 월평균상환액 | E6: =G9 -> 1100381.7 | M6: 월 상환액 | N6: =MIN(Q9:Q998) -> 546297.29
C8: 회차 | D8: 년월 | E8: 원금 | F8: 이자 | G8: 월불입금 | H8: 잔액 | I8: 잔여기간 | M8: 회차 | N8: 년월 | O8: 원금 | P8: 이자 | Q8: 월불입금 | R8: 잔액 | S8: 잔여기간 | T8: 비고
C9: 1 | D9: 43617 | E9: =IFERROR(ABS(PPMT($E$3/12,$C9,$F$4,$E$2)),0) -> 443881.7 | F9: =IF(E9>0,G9-E9,0) -> 656500 | G9: =IF(E9>0,$E$2*$E$3/12*(1+$E$3/12)^$F$4/((1+$E$3/12)^$F$4-1),0) -> 1100381.7 | H9: =$E$2-E9 -> 2.5955612e+08 | I9: =$F$4-C9 -> 359 | M9: 1 | N9: 43617 | O9: 443881.7 | P9: 656500 | Q9: 1100381.7 | R9: 2.5955612e+08 | S9: 359
C10: 2 | D10: 43647 | E10: =IFERROR(ABS(PPMT($E$3/12,$C10,$F$4,$E$2)),0) -> 445002.5 | F10: =IF(E10>0,G10-E10,0) -> 655379.2 | G10: =IF(E10>0,$E$2*$E$3/12*(1+$E$3/12)^$F$4/((1+$E$3/12)^$F$4-1),0) -> 1100381.7 | H10: =H9-E10 -> 2.5911112e+08 | I10: =$F$4-C10 -> 358 | M10: 2 | N10: 43647 | O10: 445002.5 | P10: 655379.2 | Q10: 1100381.7 | R10: 2.5911112e+08 | S10: 358
C11: 3 | D11: 43678 | E11: =IFERROR(ABS(PPMT($E$3/12,$C11,$F$4,$E$2)),0) -> 446126.13 | F11: =IF(E11>0,G11-E11,0) -> 654255.57 | G11: =IF(E11>0,$E$2*$E$3/12*(1+$E$3/12)^$F$4/((1+$E$3/12)^$F$4-1),0) -> 1100381.7 | H11: =H10-E11 -> 2.5866499e+08 | I11: =$F$4-C11 -> 357 | M11: 3 | N11: 43678 | O11: 446126.13 | P11: 654255.57 | Q11: 1100381.7 | R11: 2.5866499e+08 | S11: 357
C12: 4 | D12: 43709 | E12: =IFERROR(ABS(PPMT($E$3/12,$C12,$F$4,$E$2)),0) -> 447252.6 | F12: =IF(E12>0,G12-E12,0) -> 653129.1 | G12: =IF(E12>0,$E$2*$E$3/12*(1+$E$3/12)^$F$4/((1+$E$3/12)^$F$4-1),0) -> 1100381.7 | H12: =H11-E12 -> 2.5821774e+08 | I12: =$F$4-C12 -> 356 | M12: 4 | N12: 43709 | O12: 447252.6 | P12: 653129.1 | Q12: 1100381.7 | R12: 2.5821774e+08 | S12: 356
C13: 5 | D13: 43739 | E13: =IFERROR(ABS(PPMT($E$3/12,$C13,$F$4,$E$2)),0) -> 448381.91 | F13: =IF(E13>0,G13-E13,0) -> 651999.79 | G13: =IF(E13>0,$E$2*$E$3/12*(1+$E$3/12)^$F$4/((1+$E$3/12)^$F$4-1),0) -> 1100381.7 | H13: =H12-E13 -> 2.5776936e+08 | I13: =$F$4-C13 -> 355 | M13: 5 | N13: 43739 | O13: 448381.91 | P13: 651999.79 | Q13: 1100381.7 | R13: 2.5776936e+08 | S13: 355
C14: 6 | D14: 43770 | E14: =IFERROR(ABS(PPMT($E$3/12,$C14,$F$4,$E$2)),0) -> 449514.08 | F14: =IF(E14>0,G14-E14,0) -> 650867.62 | G14: =IF(E14>0,$E$2*$E$3/12*(1+$E$3/12)^$F$4/((1+$E$3/12)^$F$4-1),0) -> 1100381.7 | H14: =H13-E14 -> 2.5731984e+08 | I14: =$F$4-C14 -> 354 | M14: 6 | N14: 43770 | O14: 449514.08 | P14: 650867.62 | Q14: 1100381.7 | R14: 2.5731984e+08 | S14: 354
C15: 7 | D15: 43800 | E15: =IFERROR(ABS(PPMT($E$3/12,$C15,$F$4,$E$2)),0) -> 450649.1 | F15: =IF(E15>0,G15-E15,0) -> 649732.6 | G15: =IF(E15>0,$E$2*$E$3/12*(1+$E$3/12)^$F$4/((1+$E$3/12)^$F$4-1),0) -> 1100381.7 | H15: =H14-E15 -> 256869192 | I15: =$F$4-C15 -> 353 | M15: 7 | N15: 43800 | O15: 450649.1 | P15: 649732.6 | Q15: 1100381.7 | R15: 2.5686919e+08 | S15: 353
C16: 8 | D16: 43831 | E16: =IFERROR(ABS(PPMT($E$3/12,$C16,$F$4,$E$2)),0) -> 451786.99 | F16: =IF(E16>0,G16-E16,0) -> 648594.71 | G16: =IF(E16>0,$E$2*$E$3/12*(1+$E$3/12)^$F$4/((1+$E$3/12)^$F$4-1),0) -> 1100381.7 | H16: =H15-E16 -> 256417405 | I16: =$F$4-C16 -> 352 | M16: 8 | N16: 43831 | O16: 451786.99 | P16: 648594.71 | Q16: =O16+P16 -> 1100381.7 | R16: 2.564174e+08 | S16: 352
C17: 9 | D17: 43862 | E17: =IFERROR(ABS(PPMT($E$3/12,$C17,$F$4,$E$2)),0) -> 452927.75 | F17: =IF(E17>0,G17-E17,0) -> 647453.95 | G17: =IF(E17>0,$E$2*$E$3/12*(1+$E$3/12)^$F$4/((1+$E$3/12)^$F$4-1),0) -> 1100381.7 | H17: =H16-E17 -> 2.5596448e+08 | I17: =$F$4-C17 -> 351 | M17: 9 | N17: 43862 | O17: 452927.75 | P17: 647453.95 | Q17: =O17+P17 -> 1100381.7 | R17: 2.5596448e+08 | S17: 351
C18: 10 | D18: 43891 | E18: =IFERROR(ABS(PPMT($E$3/12,$C18,$F$4,$E$2)),0) -> 454071.39 | F18: =IF(E18>0,G18-E18,0) -> 646310.31 | G18: =IF(E18>0,$E$2*$E$3/12*(1+$E$3/12)^$F$4/((1+$E$3/12)^$F$4-1),0) -> 1100381.7 | H18: =H17-E18 -> 2.5551041e+08 | I18: =$F$4-C18 -> 350 | M18: 10 | N18: 43891 | O18: 454071.39 | P18: 646310.31 | Q18: =O18+P18 -> 1100381.7 | R18: 2.5551041e+08 | S18: 350
C19: 11 | D19: 43922 | E19: =IFERROR(ABS(PPMT($E$3/12,$C19,$F$4,$E$2)),0) -> 455217.92 | F19: =IF(E19>0,G19-E19,0) -> 645163.77 | G19: =IF(E19>0,$E$2*$E$3/12*(1+$E$3/12)^$F$4/((1+$E$3/12)^$F$4-1),0) -> 1100381.7 | H19: =H18-E19 -> 2.5505519e+08 | I19: =$F$4-C19 -> 349 | M19: 11 | N19: 43922 | O19: 455217.92 | P19: 645163.77 | Q19: =O19+P19 -> 1100381.7 | R19: 2.5505519e+08 | S19: 349
C20: 12 | D20: 43952 | E20: =IFERROR(ABS(PPMT($E$3/12,$C20,$F$4,$E$2)),0) -> 456367.35 | F20: =IF(E20>0,G20-E20,0) -> 644014.35 | G20: =IF(E20>0,$E$2*$E$3/12*(1+$E$3/12)^$F$4/((1+$E$3/12)^$F$4-1),0) -> 1100381.7 | H20: =H19-E20 -> 2.5459882e+08 | I20: =$F$4-C20 -> 348 | M20: 12 | N20: 43952 | O20: 456367.35 | P20: 644014.35 | Q20: =O20+P20 -> 1100381.7 | R20: 2.5459882e+08 | S20: 348
C21: 13 | D21: 43983 | E21: =IFERROR(ABS(PPMT($E$3/12,$C21,$F$4,$E$2)),0) -> 457519.68 | F21: =IF(E21>0,G21-E21,0) -> 642862.02 | G21: =IF(E21>0,$E$2*$E$3/12*(1+$E$3/12)^$F$4/((1+$E$3/12)^$F$4-1),0) -> 1100381.7 | H21: =H20-E21 -> 2.541413e+08 | I21: =$F$4-C21 -> 347 | M21: 13 | N21: 43983 | O21: 457519.68 | P21: 642862.02 | Q21: =O21+P21 -> 1100381.7 | R21: 2.541413e+08 | S21: 347
C22: 14 | D22: 44013 | E22: =IFERROR(ABS(PPMT($E$3/12,$C22,$F$4,$E$2)),0) -> 458674.91 | F22: =IF(E22>0,G22-E22,0) -> 641706.78 | G22: =IF(E22>0,$E$2*$E$3/12*(1+$E$3/12)^$F$4/((1+$E$3/12)^$F$4-1),0) -> 1100381.7 | H22: =H21-E22 -> 253682626 | I22: =$F$4-C22 -> 346 | M22: 14 | N22: 44013 | O22: =458674.913312657+1600000+500000 -> 2558674.9 | P22: =641706.784785307+1986+11509+910+3558 -> 659669.78 | Q22: =O22+P22 -> 3218344.7 | R22: =R21-O22 -> 251582626 | S22: 346 | T22: 7/20 중도상환 160만원(수수료 11,509원), 7/27 중도상환 50만원(수수료 3,558+910원)
C23: 15 | D23: 44044 | E23: =IFERROR(ABS(PPMT($E$3/12,$C23,$F$4,$E$2)),0) -> 459833.07 | F23: =IF(E23>0,G23-E23,0) -> 640548.63 | G23: =IF(E23>0,$E$2*$E$3/12*(1+$E$3/12)^$F$4/((1+$E$3/12)^$F$4-1),0) -> 1100381.7 | H23: =H22-E23 -> 2.5322279e+08 | I23: =$F$4-C23 -> 345 | M23: 15 | N23: 44044 | O23: =456026.547197131+1500000+2400000 -> 4356026.5 | P23: =635246.138224972+16344+3775+10198+2483 -> 668046.14 | Q23: =O23+P23 -> 5024072.7 | R23: 247226603 | S23: 345 | T23: 8/24 중도상환 240만원(수수료 16344+3775원) / 8/25 중도상환 150만원 (수수료 10198+2483원)
C24: 16 | D24: 44075 | E24: =IFERROR(ABS(PPMT($E$3/12,$C24,$F$4,$E$2)),0) -> 460994.15 | F24: =IF(E24>0,G24-E24,0) -> 639387.55 | G24: =IF(E24>0,$E$2*$E$3/12*(1+$E$3/12)^$F$4/((1+$E$3/12)^$F$4-1),0) -> 1100381.7 | H24: =H23-E24 -> 2.527618e+08 | I24: =$F$4-C24 -> 344 | M24: 16 | N24: 44075 | O24: =445527+500000+2000000+2000000+1000000 -> 5945527 | P24: =617934+3355+1159+4636+13423+1986+13094+6448+1738 -> 663773 | Q24: =O24+P24 -> 6609300 | R24: 241281076 | S24: 344 | T24: 9/2 50만원+200만원, 9/17 200만원, 9/26 100만원
C25: 17 | D25: 44105 | E25: =IFERROR(ABS(PPMT($E$3/12,$C25,$F$4,$E$2)),0) -> 462158.16 | F25: =IF(E25>0,G25-E25,0) -> 638223.54 | G25: =IF(E25>0,$E$2*$E$3/12*(1+$E$3/12)^$F$4/((1+$E$3/12)^$F$4-1),0) -> 1100381.7 | H25: =H24-E25 -> 2.5229964e+08 | I25: =$F$4-C25 -> 343 | M25: 17 | N25: 44105 | O25: =441167+2250000+600000 -> 3291167 | P25: =609234+1142+3659+3911+13770 -> 631716 | Q25: =O25+P25 -> 3922883 | R25: 237989909 | S25: 343 | T25: 10/26 2,250,000원 / 10/27 600,000원
C26: 18 | D26: 44136 | E26: =IFERROR(ABS(PPMT($E$3/12,$C26,$F$4,$E$2)),0) -> 463325.11 | F26: =IF(E26>0,G26-E26,0) -> 637056.59 | G26: =IF(E26>0,$E$2*$E$3/12*(1+$E$3/12)^$F$4/((1+$E$3/12)^$F$4-1),0) -> 1100381.7 | H26: =H25-E26 -> 2.5183632e+08 | I26: =$F$4-C26 -> 342 | M26: 18 | N26: 44136 | O26: 637047 | P26: 602126 | Q26: =O26+P26 -> 1239173 | R26: 237352862 | S26: 342 | T26: 11/5 200,000원
C27: 19 | D27: 44166 | E27: =IFERROR(ABS(PPMT($E$3/12,$C27,$F$4,$E$2)),0) -> 464495 | F27: =IF(E27>0,G27-E27,0) -> 635886.7 | G27: =IF(E27>0,$E$2*$E$3/12*(1+$E$3/12)^$F$4/((1+$E$3/12)^$F$4-1),0) -> 1100381.7 | H27: =H26-E27 -> 2.5137182e+08 | I27: =$F$4-C27 -> 341 | M27: 19 | N27: 44166 | O27: =16000000+408271+100000 -> 16508271 | P27: =38413+91094+558915+33+563 -> 689018 | Q27: =O27+P27 -> 17197289 | R27: =R26-O27 -> 220844591 | S27: 341 | T27: 12/4 16,000,000원 + 100,000원
C28: 20 | D28: 44197 | E28: =IFERROR(ABS(PPMT($E$3/12,$C28,$F$4,$E$2)),0) -> 465667.85 | F28: =IF(E28>0,G28-E28,0) -> 634713.85 | G28: =IF(E28>0,$E$2*$E$3/12*(1+$E$3/12)^$F$4/((1+$E$3/12)^$F$4-1),0) -> 1100381.7 | H28: =H27-E28 -> 2.5090615e+08 | I28: =$F$4-C28 -> 340 | M28: 20 | N28: 44197 | O28: =1344591+406625+1500000 -> 3251216 | P28: =554237+3005+7243+1618+7801 -> 573904 | Q28: =O28+P28 -> 3825120 | R28: =R27-O28 -> 217593375 | S28: 340 | T28: 1/1 1,354,839원, 1/18 1,500,000원
C29: 21 | D29: 44228 | E29: =IFERROR(ABS(PPMT($E$3/12,$C29,$F$4,$E$2)),0) -> 466843.66 | F29: =IF(E29>0,G29-E29,0) -> 633538.04 | G29: =IF(E29>0,$E$2*$E$3/12*(1+$E$3/12)^$F$4/((1+$E$3/12)^$F$4-1),0) -> 1100381.7 | H29: =H28-E29 -> 250439309 | I29: =$F$4-C29 -> 339 | M29: 21 | N29: 44228 | O29: =404860.889494676+1600000+1000000 -> 3004860.9 | P29: =549423.271874975+1195+7848+996+4872 -> 564334.27 | Q29: =O29+P29 -> 3569195.2 | R29: =R28-O29 -> 2.1458851e+08 | S29: 339 | T29: 2/14 1,600,000원, 2/17 1,000,000원
C30: 22 | D30: 44256 | E30: =IFERROR(ABS(PPMT($E$3/12,$C30,$F$4,$E$2)),0) -> 468022.44 | F30: =IF(E30>0,G30-E30,0) -> 632359.26 | G30: =IF(E30>0,$E$2*$E$3/12*(1+$E$3/12)^$F$4/((1+$E$3/12)^$F$4-1),0) -> 1100381.7 | H30: =H29-E30 -> 2.4997129e+08 | I30: =$F$4-C30 -> 338 | M30: 22 | N30: 44256 | O30: =401025+1150000+1000000+2000000+2000000+4000000 -> 10551025 | P30: =541835+5401+4913+10835+11267+26282 -> 600533 | Q30: =O30+P30 -> 11151558 | R30: =R29-O30 -> 2.0403749e+08 | S30: 338 | T30: 3/5 1,150,000원, 3/8 1,000,000원, 3/15 2,000,000원, 3/18 2,000,000원, 3/31 4,000,000원
C31: 23 | D31: 44287 | E31: =IFERROR(ABS(PPMT($E$3/12,$C31,$F$4,$E$2)),0) -> 469204.2 | F31: =IF(E31>0,G31-E31,0) -> 631177.5 | G31: =IF(E31>0,$E$2*$E$3/12*(1+$E$3/12)^$F$4/((1+$E$3/12)^$F$4-1),0) -> 1100381.7 | H31: =H30-E31 -> 2.4950208e+08 | I31: =$F$4-C31 -> 337 | M31: 23 | N31: 44287 | O31: =382985+2000000+2000000+2000000+1154504+500000 -> 8037489 | P31: =515194+9147+10732+12173+7109+3078 -> 557433 | Q31: =O31+P31 -> 8594922 | R31: =R30-O31 -> 1.96e+08 | S31: 337 | T31: 4/8 2,000,000원, 4/19 2,000,000원, 4/20 2,000,000원, 4/30 1,654,504원
C32: 24 | D32: 44317 | E32: =IFERROR(ABS(PPMT($E$3/12,$C32,$F$4,$E$2)),0) -> 470388.94 | F32: =IF(E32>0,G32-E32,0) -> 629992.76 | G32: =IF(E32>0,$E$2*$E$3/12*(1+$E$3/12)^$F$4/((1+$E$3/12)^$F$4-1),0) -> 1100381.7 | H32: =H31-E32 -> 2.4903169e+08 | I32: =$F$4-C32 -> 336 | M32: 24 | N32: 44317 | O32: =369520+1100000 -> 1469520 | P32: =494899.999999978+5700 -> 500600 | Q32: =O32+P32 -> 1970120 | R32: =R31-O32 -> 1.9453048e+08 | S32: 336 | T32: 5/21 1,110,000원
C33: 25 | D33: 44348 | E33: =IFERROR(ABS(PPMT($E$3/12,$C33,$F$4,$E$2)),0) -> 471576.67 | F33: =IF(E33>0,G33-E33,0) -> 628805.03 | G33: =IF(E33>0,$E$2*$E$3/12*(1+$E$3/12)^$F$4/((1+$E$3/12)^$F$4-1),0) -> 1100381.7 | H33: =H32-E33 -> 2.4856012e+08 | I33: =$F$4-C33 -> 335 | M33: 25 | N33: 44348 | O33: =1700000+3000000+368371 -> 5068371 | P33: =491189+1128+6123+2988+10675 -> 512103 | Q33: =O33+P33 -> 5580474 | R33: =R32-O33 -> 1.8946211e+08 | S33: 335 | T33: 6/13 1,700,000원 6/17 3,000,000원
C34: 26 | D34: 44378 | E34: =IFERROR(ABS(PPMT($E$3/12,$C34,$F$4,$E$2)),0) -> 472767.4 | F34: =IF(E34>0,G34-E34,0) -> 627614.29 | G34: =IF(E34>0,$E$2*$E$3/12*(1+$E$3/12)^$F$4/((1+$E$3/12)^$F$4-1),0) -> 1100381.7 | H34: =H33-E34 -> 2.4808735e+08 | I34: =$F$4-C34 -> 334 | M34: 26 | N34: 44378 | O34: =1250000+357984+1600000 -> 3207984 | P34: =2697+4256+475235+4940+3320 -> 490448 | Q34: =O34+P34 -> 3698432 | R34: =R33-O34 -> 1.8625413e+08 | S34: 334 | T34: 7/1 1,250,000원, 7/30 1,600,000원
C35: 27 | D35: 44409 | E35: =IFERROR(ABS(PPMT($E$3/12,$C35,$F$4,$E$2)),0) -> 473961.14 | F35: =IF(E35>0,G35-E35,0) -> 626420.56 | G35: =IF(E35>0,$E$2*$E$3/12*(1+$E$3/12)^$F$4/((1+$E$3/12)^$F$4-1),0) -> 1100381.7 | H35: =H34-E35 -> 2.4761339e+08 | I35: =$F$4-C35 -> 333 | M35: 27 | N35: 44409 | O35: =550000+355831+1500000 -> 2405831 | P35: =45+1656+470291+2241+4237 -> 478470 | Q35: =O35+P35 -> 2884301 | R35: =R34-O35 -> 1.8384829e+08 | S35: 333 | T35: 8/5 550,000원, 8/23 1,500,000원
C36: 28 | D36: 44440 | E36: =IFERROR(ABS(PPMT($E$3/12,$C36,$F$4,$E$2)),0) -> 475157.89 | F36: =IF(E36>0,G36-E36,0) -> 625223.81 | G36: =IF(E36>0,$E$2*$E$3/12*(1+$E$3/12)^$F$4/((1+$E$3/12)^$F$4-1),0) -> 1100381.7 | H36: =H35-E36 -> 2.4713823e+08 | I36: =$F$4-C36 -> 332 | M36: 28 | N36: 44440 | O36: =352796+2200000 -> 2552796 | P36: =464216+7962 -> 472178 | Q36: =O36+P36 -> 3024974 | R36: =R35-O36 -> 1.812955e+08 | S36: 332 | T36: 9/18 2,220,000원
C37: 29 | D37: 44470 | E37: =IFERROR(ABS(PPMT($E$3/12,$C37,$F$4,$E$2)),0) -> 476357.67 | F37: =IF(E37>0,G37-E37,0) -> 624024.03 | G37: =IF(E37>0,$E$2*$E$3/12*(1+$E$3/12)^$F$4/((1+$E$3/12)^$F$4-1),0) -> 1100381.7 | H37: =H36-E37 -> 2.4666187e+08 | I37: =$F$4-C37 -> 331 | M37: 29 | N37: 44470 | O37: =1700000+346170+2500000 -> 4546170 | P37: =3951+4039+453478+10208 -> 471676 | Q37: =O37+P37 -> 5017846 | R37: =R36-O37 -> 1.7674933e+08 | S37: 331 | T37: 10/3 1,700,000원, 10/29 2,500,000원
C38: 30 | D38: 44501 | E38: =IFERROR(ABS(PPMT($E$3/12,$C38,$F$4,$E$2)),0) -> 477560.47 | F38: =IF(E38>0,G38-E38,0) -> 622821.23 | G38: =IF(E38>0,$E$2*$E$3/12*(1+$E$3/12)^$F$4/((1+$E$3/12)^$F$4-1),0) -> 1100381.7 | H38: =H37-E38 -> 2.4618431e+08 | I38: =$F$4-C38 -> 330 | M38: 30 | N38: 44501 | O38: =342203+1000000+2000000 -> 3342203 | P38: =446292+2735+5902 -> 454929 | Q38: =O38+P38 -> 3797132 | R38: =R37-O38 -> 1.7340713e+08 | S38: 330 | T38: 11/15 1,000,000원, 11/18 2,000,000원
C39: 31 | D39: 44531 | E39: =IFERROR(ABS(PPMT($E$3/12,$C39,$F$4,$E$2)),0) -> 478766.31 | F39: =IF(E39>0,G39-E39,0) -> 621615.39 | G39: =IF(E39>0,$E$2*$E$3/12*(1+$E$3/12)^$F$4/((1+$E$3/12)^$F$4-1),0) -> 1100381.7 | H39: =H38-E39 -> 2.4570555e+08 | I39: =$F$4-C39 -> 329 | M39: 31 | N39: 44531 | O39: =2000000+333344+2000000+350000+1000000+2500000 -> 8183344 | P39: =7775+432802+3516+615+21118+6376 -> 472202 | Q39: =O39+P39 -> 8655546 | R39: =R38-O39 -> 1.6522378e+08 | S39: 329 | T39: 12/1 2,000,000원, 12/6 2,350,000원 12/10 1,000,000원, 12/17 2,500,000원
C40: 32 | D40: 44562 | E40: =IFERROR(ABS(PPMT($E$3/12,$C40,$F$4,$E$2)),0) -> 479975.19 | F40: =IF(E40>0,G40-E40,0) -> 620406.5 | G40: =IF(E40>0,$E$2*$E$3/12*(1+$E$3/12)^$F$4/((1+$E$3/12)^$F$4-1),0) -> 1100381.7 | H40: =H39-E40 -> 2.4522557e+08 | I40: =$F$4-C40 -> 328 | M40: 32 | N40: 44562 | O40: =2000000+318850+3700000+1800000 -> 7818850 | P40: =7263+412140+8181+5406 -> 432990 | Q40: =O40+P40 -> 8251840 | R40: =R39-O40 -> 1.5740493e+08 | S40: 328 | T40: 1/1 2,000,000원, 1/27 3,700,000원, 1/28 1,800,000원
C41: 33 | D41: 44593 | E41: =IFERROR(ABS(PPMT($E$3/12,$C41,$F$4,$E$2)),0) -> 481187.13 | F41: =IF(E41>0,G41-E41,0) -> 619194.57 | G41: =IF(E41>0,$E$2*$E$3/12*(1+$E$3/12)^$F$4/((1+$E$3/12)^$F$4-1),0) -> 1100381.7 | H41: =H40-E41 -> 2.4474438e+08 | I41: =$F$4-C41 -> 327 | M41: 33 | N41: 44593 | O41: =308863+1100000+2200000 -> 3608863 | P41: =397447+2534+5862 -> 405843 | Q41: =O41+P41 -> 4014706 | R41: =R40-O41 -> 1.5379607e+08 | S41: 327 | T41: 2/23 1,100,000원, 2/28 2,200,000원
...

Sheet 주담대_이자율계산
C2: 대출액 | E2: 1.1957322e+08
C3: 이율(%) | E3: 0.0303
C4: 상환기간(개월) | E4: 319
C5: 총 대출이자 | E5: =G9*E4-E2 -> 54695611
C6: 월평균상환액 | E6: =G9 -> 546297.29
C8: 회차 | D8: 변환회차 | E8: 원금 | F8: 이자 | G8: 월불입금 | H8: 잔액 | I8: 잔여기간
C9: 1 | D9: =360-E4+1 -> 42 | E9: =IFERROR(ABS(PPMT($E$3/12,$C9,$E$4,$E$2)),0) -> 244374.9 | F9: =IF(E9>0,G9-E9,0) -> 301922.39 | G9: =IF(E9>0,$E$2*$E$3/12*(1+$E$3/12)^$E$4/((1+$E$3/12)^$E$4-1),0) -> 546297.29 | H9: =$E$2-E9 -> 1.1932885e+08 | I9: =$E$4-C9 -> 318
C10: =C9+1 -> 2 | D10: =D9+1 -> 43 | E10: =IFERROR(ABS(PPMT($E$3/12,$C10,$E$4,$E$2)),0) -> 244991.94 | F10: =IF(E10>0,G10-E10,0) -> 301305.34 | G10: =IF(E10>0,$E$2*$E$3/12*(1+$E$3/12)^$E$4/((1+$E$3/12)^$E$4-1),0) -> 546297.29 | H10: =H9-E10 -> 1.1908386e+08 | I10: =$E$4-C10 -> 317
C11: =C10+1 -> 3 | D11: =D10+1 -> 44 | E11: =IFERROR(ABS(PPMT($E$3/12,$C11,$E$4,$E$2)),0) -> 245610.55 | F11: =IF(E11>0,G11-E11,0) -> 300686.74 | G11: =IF(E11>0,$E$2*$E$3/12*(1+$E$3/12)^$E$4/((1+$E$3/12)^$E$4-1),0) -> 546297.29 | H11: =H10-E11 -> 1.1883825e+08 | I11: =$E$4-C11 -> 316
C12: =C11+1 -> 4 | D12: =D11+1 -> 45 | E12: =IFERROR(ABS(PPMT($E$3/12,$C12,$E$4,$E$2)),0) -> 246230.72 | F12: =IF(E12>0,G12-E12,0) -> 300066.57 | G12: =IF(E12>0,$E$2*$E$3/12*(1+$E$3/12)^$E$4/((1+$E$3/12)^$E$4-1),0) -> 546297.29 | H12: =H11-E12 -> 118592015 | I12: =$E$4-C12 -> 315
C13: =C12+1 -> 5 | D13: =D12+1 -> 46 | E13: =IFERROR(ABS(PPMT($E$3/12,$C13,$E$4,$E$2)),0) -> 246852.45 | F13: =IF(E13>0,G13-E13,0) -> 299444.84 | G13: =IF(E13>0,$E$2*$E$3/12*(1+$E$3/12)^$E$4/((1+$E$3/12)^$E$4-1),0) -> 546297.29 | H13: =H12-E13 -> 1.1834516e+08 | I13: =$E$4-C13 -> 314
C14: =C13+1 -> 6 | D14: =D13+1 -> 47 | E14: =IFERROR(ABS(PPMT($E$3/12,$C14,$E$4,$E$2)),0) -> 247475.75 | F14: =IF(E14>0,G14-E14,0) -> 298821.54 | G14: =IF(E14>0,$E$2*$E$3/12*(1+$E$3/12)^$E$4/((1+$E$3/12)^$E$4-1),0) -> 546297.29 | H14: =H13-E14 -> 1.1809769e+08 | I14: =$E$4-C14 -> 313
C15: =C14+1 -> 7 | D15: =D14+1 -> 48 | E15: =IFERROR(ABS(PPMT($E$3/12,$C15,$E$4,$E$2)),0) -> 248100.63 | F15: =IF(E15>0,G15-E15,0) -> 298196.66 | G15: =IF(E15>0,$E$2*$E$3/12*(1+$E$3/12)^$E$4/((1+$E$3/12)^$E$4-1),0) -> 546297.29 | H15: =H14-E15 -> 1.1784959e+08 | I15: =$E$4-C15 -> 312
C16: =C15+1 -> 8 | D16: =D15+1 -> 49 | E16: =IFERROR(ABS(PPMT($E$3/12,$C16,$E$4,$E$2)),0) -> 248727.08 | F16: =IF(E16>0,G16-E16,0) -> 297570.21 | G16: =IF(E16>0,$E$2*$E$3/12*(1+$E$3/12)^$E$4/((1+$E$3/12)^$E$4-1),0) -> 546297.29 | H16: =H15-E16 -> 1.1760086e+08 | I16: =$E$4-C16 -> 311
C17: =C16+1 -> 9 | D17: =D16+1 -> 50 | E17: =IFERROR(ABS(PPMT($E$3/12,$C17,$E$4,$E$2)),0) -> 249355.12 | F17: =IF(E17>0,G17-E17,0) -> 296942.17 | G17: =IF(E17>0,$E$2*$E$3/12*(1+$E$3/12)^$E$4/((1+$E$3/12)^$E$4-1),0) -> 546297.29 | H17: =H16-E17 -> 117351504 | I17: =$E$4-C17 -> 310
C18: =C17+1 -> 10 | D18: =D17+1 -> 51 | E18: =IFERROR(ABS(PPMT($E$3/12,$C18,$E$4,$E$2)),0) -> 249984.74 | F18: =IF(E18>0,G18-E18,0) -> 296312.55 | G18: =IF(E18>0,$E$2*$E$3/12*(1+$E$3/12)^$E$4/((1+$E$3/12)^$E$4-1),0) -> 546297.29 | H18: =H17-E18 -> 1.1710152e+08 | I18: =$E$4-C18 -> 309
C19: =C18+1 -> 11 | D19: =D18+1 -> 52 | E19: =IFERROR(ABS(PPMT($E$3/12,$C19,$E$4,$E$2)),0) -> 250615.95 | F19: =IF(E19>0,G19-E19,0) -> 295681.34 | G19: =IF(E19>0,$E$2*$E$3/12*(1+$E$3/12)^$E$4/((1+$E$3/12)^$E$4-1),0) -> 546297.29 | H19: =H18-E19 -> 1.168509e+08 | I19: =$E$4-C19 -> 308
C20: =C19+1 -> 12 | D20: =D19+1 -> 53 | E20: =IFERROR(ABS(PPMT($E$3/12,$C20,$E$4,$E$2)),0) -> 251248.75 | F20: =IF(E20>0,G20-E20,0) -> 295048.53 | G20: =IF(E20>0,$E$2*$E$3/12*(1+$E$3/12)^$E$4/((1+$E$3/12)^$E$4-1),0) -> 546297.29 | H20: =H19-E20 -> 1.1659965e+08 | I20: =$E$4-C20 -> 307
C21: =C20+1 -> 13 | D21: =D20+1 -> 54 | E21: =IFERROR(ABS(PPMT($E$3/12,$C21,$E$4,$E$2)),0) -> 251883.16 | F21: =IF(E21>0,G21-E21,0) -> 294414.13 | G21: =IF(E21>0,$E$2*$E$3/12*(1+$E$3/12)^$E$4/((1+$E$3/12)^$E$4-1),0) -> 546297.29 | H21: =H20-E21 -> 1.1634777e+08 | I21: =$E$4-C21 -> 306
... C330: =C329+1 -> 322 | D330: =D329+1 -> 363 | E330: =IFERROR(ABS(PPMT($E$3/12,$C330,$E$4,$E$2)),0) -> 0 | F330: =IF(E330>0,G330-E330,0) -> 0 | G330: =IF(E330>0,$E$2*$E$3/12*(1+$E$3/12)^$E$4/((1+$E$3/12)^$E$4-1),0) -> 0 | H330: =H329-E330 -> 5.2866526e-06 | I330: =$E$4-C330 -> -3

Sheet info
A2: 1. 지출분류
B3: no. | C3: 분류 | D3: 변동비 구분 | E3: 고정비 구분 | F3: 여행/공연비 구분 | G3: 저축/대출상환
B4: 1 | C4: 변동비 | D4: 식비 | E4: 경조사비 | F4: 문화생활 | G4: 주택담보대출 원금
B5: 2 | C5: 고정비 | D5: 외식비 | E5: 관리비 | F5: 국내여행 | G5: 신용대출 원금
B6: 3 | C6: 여행공연비 | D6: 의류 | E6: 교통비 | F6: 해외여행
B7: 4 | C7: 대출상환 | D7: 모임비 | E7: 렌탈비
B8: 5 | D8: 출근식대 | E8: 문경
B9: 6 | D9: 커피 | E9: 미용
B10: 7 | D10: 담배 | E10: 비품 및 수선유지비
B11: 8 | D11: 기타구매 | E11: 세금
B12: 9 | E12: 신용대출 이자
B13: 10 | E13: 예비비
B14: 11 | E14: 취미
B15: 12 | E15: 보험
B16: 13 | E16: 자동차운행
B17: 14 | E17: 주택담보대출 이자
B18: 15 | E18: 통신비
B19: 16 | E19: 의료/건강
B20: 17 | E20: 브랜디식대
B21: 18 | E21: 교육비
B22: 19
B23: 20

Sheet 신용_이자율계산
B2: 대출액 | C2: 28880000 | D2: =C2 -> 28880000 | G2: 대출액 | H2: 36000000 | I2: =H2 -> 36000000
B3: 이율(%) | C3: 0.0271 | G3: 이율(%) | H3: 0.027
B4: 상환기간(년) | C4: 1 | D4: =C4*12 -> 12 | G4: 상환기간(년) | H4: 3 | I4: =H4*12 -> 36
B5: 총 대출이자 | C5: =E9*D4-C2 -> 425687.54 | G5: 총 대출이자 | H5: =J9*I4-H2 -> 1518143.6 | I5: 7359668 | J5: =H5-I5 -> -5841524.4
B6: 월평균상환액 | C6: =E9 -> 2442140.6 | G6: 월평균상환액 | H6: =J9 -> 1042170.7
B8: 회차 | C8: 원금 | D8: 이자 | E8: 월불입금 | G8: 회차 | H8: 원금 | I8: 이자 | J8: 월불입금
B9: 1 | C9: =IFERROR(ABS(PPMT($C$3/12,$B9,$D$4,$C$2)),0) -> 2376920 | D9: =IF(C9>0,E9-C9,0) -> 65220.667 | E9: =IF(C9>0,$C$2*$C$3/12*(1+$C$3/12)^$D$4/((1+$C$3/12)^$D$4-1),0) -> 2442140.6 | G9: 1 | H9: =IFERROR(ABS(PPMT($H$3/12,$G9,$I$4,$H$2)),0) -> 961170.65 | I9: =IF(H9>0,J9-H9,0) -> 81000 | J9: =IF(H9>0,$H$2*$H$3/12*(1+$H$3/12)^$I$4/((1+$H$3/12)^$I$4-1),0) -> 1042170.7
B10: 2 | C10: =IFERROR(ABS(PPMT($C$3/12,$B10,$D$4,$C$2)),0) -> 2382287.8 | D10: =IF(C10>0,E10-C10,0) -> 59852.789 | E10: =IF(C10>0,$C$2*$C$3/12*(1+$C$3/12)^$D$4/((1+$C$3/12)^$D$4-1),0) -> 2442140.6 | G10: 2 | H10: =IFERROR(ABS(PPMT($H$3/12,$G10,$I$4,$H$2)),0) -> 963333.29 | I10: =IF(H10>0,J10-H10,0) -> 78837.366 | J10: =IF(H10>0,$H$2*$H$3/12*(1+$H$3/12)^$I$4/((1+$H$3/12)^$I$4-1),0) -> 1042170.7
B11: 3 | C11: =IFERROR(ABS(PPMT($C$3/12,$B11,$D$4,$C$2)),0) -> 2387667.8 | D11: =IF(C11>0,E11-C11,0) -> 54472.789 | E11: =IF(C11>0,$C$2*$C$3/12*(1+$C$3/12)^$D$4/((1+$C$3/12)^$D$4-1),0) -> 2442140.6 | G11: 3 | H11: =IFERROR(ABS(PPMT($H$3/12,$G11,$I$4,$H$2)),0) -> 965500.79 | I11: =IF(H11>0,J11-H11,0) -> 76669.866 | J11: =IF(H11>0,$H$2*$H$3/12*(1+$H$3/12)^$I$4/((1+$H$3/12)^$I$4-1),0) -> 1042170.7
B12: 4 | C12: =IFERROR(ABS(PPMT($C$3/12,$B12,$D$4,$C$2)),0) -> 2393060 | D12: =IF(C12>0,E12-C12,0) -> 49080.639 | E12: =IF(C12>0,$C$2*$C$3/12*(1+$C$3/12)^$D$4/((1+$C$3/12)^$D$4-1),0) -> 2442140.6 | G12: 4 | H12: =IFERROR(ABS(PPMT($H$3/12,$G12,$I$4,$H$2)),0) -> 967673.17 | I12: =IF(H12>0,J12-H12,0) -> 74497.489 | J12: =IF(H12>0,$H$2*$H$3/12*(1+$H$3/12)^$I$4/((1+$H$3/12)^$I$4-1),0) -> 1042170.7
B13: 5 | C13: =IFERROR(ABS(PPMT($C$3/12,$B13,$D$4,$C$2)),0) -> 2398464.3 | D13: =IF(C13>0,E13-C13,0) -> 43676.312 | E13: =IF(C13>0,$C$2*$C$3/12*(1+$C$3/12)^$D$4/((1+$C$3/12)^$D$4-1),0) -> 2442140.6 | G13: 5 | H13: =IFERROR(ABS(PPMT($H$3/12,$G13,$I$4,$H$2)),0) -> 969850.43 | I13: =IF(H13>0,J13-H13,0) -> 72320.225 | J13: =IF(H13>0,$H$2*$H$3/12*(1+$H$3/12)^$I$4/((1+$H$3/12)^$I$4-1),0) -> 1042170.7
B14: 6 | C14: =IFERROR(ABS(PPMT($C$3/12,$B14,$D$4,$C$2)),0) -> 2403880.8 | D14: =IF(C14>0,E14-C14,0) -> 38259.78 | E14: =IF(C14>0,$C$2*$C$3/12*(1+$C$3/12)^$D$4/((1+$C$3/12)^$D$4-1),0) -> 2442140.6 | G14: 6 | H14: =IFERROR(ABS(PPMT($H$3/12,$G14,$I$4,$H$2)),0) -> 972032.59 | I14: =IF(H14>0,J14-H14,0) -> 70138.061 | J14: =IF(H14>0,$H$2*$H$3/12*(1+$H$3/12)^$I$4/((1+$H$3/12)^$I$4-1),0) -> 1042170.7
B15: 7 | C15: =IFERROR(ABS(PPMT($C$3/12,$B15,$D$4,$C$2)),0) -> 2409309.6 | D15: =IF(C15>0,E15-C15,0) -> 32831.016 | E15: =IF(C15>0,$C$2*$C$3/12*(1+$C$3/12)^$D$4/((1+$C$3/12)^$D$4-1),0) -> 2442140.6 | G15: 12 | H15: =IFERROR(ABS(PPMT($H$3/12,$G15,$I$4,$H$2)),0) -> 985229.07 | I15: =IF(H15>0,J15-H15,0) -> 56941.586 | J15: =IF(H15>0,$H$2*$H$3/12*(1+$H$3/12)^$I$4/((1+$H$3/12)^$I$4-1),0) -> 1042170.7
B16: 8 | C16: =IFERROR(ABS(PPMT($C$3/12,$B16,$D$4,$C$2)),0) -> 2414750.6 | D16: =IF(C16>0,E16-C16,0) -> 27389.992 | E16: =IF(C16>0,$C$2*$C$3/12*(1+$C$3/12)^$D$4/((1+$C$3/12)^$D$4-1),0) -> 2442140.6 | G16: =12*2 -> 24 | H16: =IFERROR(ABS(PPMT($H$3/12,$G16,$I$4,$H$2)),0) -> 1012161.9 | I16: =IF(H16>0,J16-H16,0) -> 30008.73 | J16: =IF(H16>0,$H$2*$H$3/12*(1+$H$3/12)^$I$4/((1+$H$3/12)^$I$4-1),0) -> 1042170.7
B17: 9 | C17: =IFERROR(ABS(PPMT($C$3/12,$B17,$D$4,$C$2)),0) -> 2420203.9 | D17: =IF(C17>0,E17-C17,0) -> 21936.68 | E17: =IF(C17>0,$C$2*$C$3/12*(1+$C$3/12)^$D$4/((1+$C$3/12)^$D$4-1),0) -> 2442140.6 | G17: =12*3 -> 36 | H17: =IFERROR(ABS(PPMT($H$3/12,$G17,$I$4,$H$2)),0) -> 1039831 | I17: =IF(H17>0,J17-H17,0) -> 2339.6198 | J17: =IF(H17>0,$H$2*$H$3/12*(1+$H$3/12)^$I$4/((1+$H$3/12)^$I$4-1),0) -> 1042170.7
B18: 10 | C18: =IFERROR(ABS(PPMT($C$3/12,$B18,$D$4,$C$2)),0) -> 2425669.6 | D18: =IF(C18>0,E18-C18,0) -> 16471.053 | E18: =IF(C18>0,$C$2*$C$3/12*(1+$C$3/12)^$D$4/((1+$C$3/12)^$D$4-1),0) -> 2442140.6 | G18: =12*4 -> 48 | H18: =IFERROR(ABS(PPMT($H$3/12,$G18,$I$4,$H$2)),0) -> 0 | I18: =IF(H18>0,J18-H18,0) -> 0 | J18: =IF(H18>0,$H$2*$H$3/12*(1+$H$3/12)^$I$4/((1+$H$3/12)^$I$4-1),0) -> 0
B19: 11 | C19: =IFERROR(ABS(PPMT($C$3/12,$B19,$D$4,$C$2)),0) -> 2431147.5 | D19: =IF(C19>0,E19-C19,0) -> 10993.082 | E19: =IF(C19>0,$C$2*$C$3/12*(1+$C$3/12)^$D$4/((1+$C$3/12)^$D$4-1),0) -> 2442140.6 | G19: =12*5 -> 60 | H19: =IFERROR(ABS(PPMT($H$3/12,$G19,$I$4,$H$2)),0) -> 0 | I19: =IF(H19>0,J19-H19,0) -> 0 | J19: =IF(H19>0,$H$2*$H$3/12*(1+$H$3/12)^$I$4/((1+$H$3/12)^$I$4-1),0) -> 0
B20: 12 | C20: =IFERROR(ABS(PPMT($C$3/12,$B20,$D$4,$C$2)),0) -> 2436637.9 | D20: =IF(C20>0,E20-C20,0) -> 5502.7406 | E20: =IF(C20>0,$C$2*$C$3/12*(1+$C$3/12)^$D$4/((1+$C$3/12)^$D$4-1),0) -> 2442140.6 | G20: =12*6 -> 72 | H20: =IFERROR(ABS(PPMT($H$3/12,$G20,$I$4,$H$2)),0) -> 0 | I20: =IF(H20>0,J20-H20,0) -> 0 | J20: =IF(H20>0,$H$2*$H$3/12*(1+$H$3/12)^$I$4/((1+$H$3/12)^$I$4-1),0) -> 0
B21: 13 | C21: =IFERROR(ABS(PPMT($C$3/12,$B21,$D$4,$C$2)),0) -> 0 | D21: =IF(C21>0,E21-C21,0) -> 0 | E21: =IF(C21>0,$C$2*$C$3/12*(1+$C$3/12)^$D$4/((1+$C$3/12)^$D$4-1),0) -> 0 | G21: =12*7 -> 84 | H21: =IFERROR(ABS(PPMT($H$3/12,$G21,$I$4,$H$2)),0) -> 0 | I21: =IF(H21>0,J21-H21,0) -> 0 | J21: =IF(H21>0,$H$2*$H$3/12*(1+$H$3/12)^$I$4/((1+$H$3/12)^$I$4-1),0) -> 0
B22: 14 | C22: =IFERROR(ABS(PPMT($C$3/12,$B22,$D$4,$C$2)),0) -> 0 | D22: =IF(C22>0,E22-C22,0) -> 0 | E22: =IF(C22>0,$C$2*$C$3/12*(1+$C$3/12)^$D$4/((1+$C$3/12)^$D$4-1),0) -> 0 | G22: =12*8 -> 96 | H22: =IFERROR(ABS(PPMT($H$3/12,$G22,$I$4,$H$2)),0) -> 0 | I22: =IF(H22>0,J22-H22,0) -> 0 | J22: =IF(H22>0,$H$2*$H$3/12*(1+$H$3/12)^$I$4/((1+$H$3/12)^$I$4-1),0) -> 0
B23: 15 | C23: =IFERROR(ABS(PPMT($C$3/12,$B23,$D$4,$C$2)),0) -> 0 | D23: =IF(C23>0,E23-C23,0) -> 0 | E23: =IF(C23>0,$C$2*$C$3/12*(1+$C$3/12)^$D$4/((1+$C$3/12)^$D$4-1),0) -> 0 | G23: =12*9 -> 108 | H23: =IFERROR(ABS(PPMT($H$3/12,$G23,$I$4,$H$2)),0) -> 0 | I23: =IF(H23>0,J23-H23,0) -> 0 | J23: =IF(H23>0,$H$2*$H$3/12*(1+$H$3/12)^$I$4/((1+$H$3/12)^$I$4-1),0) -> 0
B24: 16 | C24: =IFERROR(ABS(PPMT($C$3/12,$B24,$D$4,$C$2)),0) -> 0 | D24: =IF(C24>0,E24-C24,0) -> 0 | E24: =IF(C24>0,$C$2*$C$3/12*(1+$C$3/12)^$D$4/((1+$C$3/12)^$D$4-1),0) -> 0 | G24: =12*10 -> 120 | H24: =IFERROR(ABS(PPMT($H$3/12,$G24,$I$4,$H$2)),0) -> 0 | I24: =IF(H24>0,J24-H24,0) -> 0 | J24: =IF(H24>0,$H$2*$H$3/12*(1+$H$3/12)^$I$4/((1+$H$3/12)^$I$4-1),0) -> 0
B25: 17 | C25: =IFERROR(ABS(PPMT($C$3/12,$B25,$D$4,$C$2)),0) -> 0 | D25: =IF(C25>0,E25-C25,0) -> 0 | E25: =IF(C25>0,$C$2*$C$3/12*(1+$C$3/12)^$D$4/((1+$C$3/12)^$D$4-1),0) -> 0 | G25: =12*12 -> 144 | H25: =IFERROR(ABS(PPMT($H$3/12,$G25,$I$4,$H$2)),0) -> 0 | I25: =IF(H25>0,J25-H25,0) -> 0 | J25: =IF(H25>0,$H$2*$H$3/12*(1+$H$3/12)^$I$4/((1+$H$3/12)^$I$4-1),0) -> 0
B26: 18 | C26: =IFERROR(ABS(PPMT($C$3/12,$B26,$D$4,$C$2)),0) -> 0 | D26: =IF(C26>0,E26-C26,0) -> 0 | E26: =IF(C26>0,$C$2*$C$3/12*(1+$C$3/12)^$D$4/((1+$C$3/12)^$D$4-1),0) -> 0 | G26: =12*15 -> 180 | H26: =IFERROR(ABS(PPMT($H$3/12,$G26,$I$4,$H$2)),0) -> 0 | I26: =IF(H26>0,J26-H26,0) -> 0 | J26: =IF(H26>0,$H$2*$H$3/12*(1+$H$3/12)^$I$4/((1+$H$3/12)^$I$4-1),0) -> 0
B27: 19 | C27: =IFERROR(ABS(PPMT($C$3/12,$B27,$D$4,$C$2)),0) -> 0 | D27: =IF(C27>0,E27-C27,0) -> 0 | E27: =IF(C27>0,$C$2*$C$3/12*(1+$C$3/12)^$D$4/((1+$C$3/12)^$D$4-1),0) -> 0
B28: 20 | C28: =IFERROR(ABS(PPMT($C$3/12,$B28,$D$4,$C$2)),0) -> 0 | D28: =IF(C28>0,E28-C28,0) -> 0 | E28: =IF(C28>0,$C$2*$C$3/12*(1+$C$3/12)^$D$4/((1+$C$3/12)^$D$4-1),0) -> 0
B29: 21 | C29: =IFERROR(ABS(PPMT($C$3/12,$B29,$D$4,$C$2)),0) -> 0 | D29: =IF(C29>0,E29-C29,0) -> 0 | E29: =IF(C29>0,$C$2*$C$3/12*(1+$C$3/12)^$D$4/((1+$C$3/12)^$D$4-1),0) -> 0
B30: 22 | C30: =IFERROR(ABS(PPMT($C$3/12,$B30,$D$4,$C$2)),0) -> 0 | D30: =IF(C30>0,E30-C30,0) -> 0 | E30: =IF(C30>0,$C$2*$C$3/12*(1+$C$3/12)^$D$4/((1+$C$3/12)^$D$4-1),0) -> 0
B31: 23 | C31: =IFERROR(ABS(PPMT($C$3/12,$B31,$D$4,$C$2)),0) -> 0 | D31: =IF(C31>0,E31-C31,0) -> 0 | E31: =IF(C31>0,$C$2*$C$3/12*(1+$C$3/12)^$D$4/((1+$C$3/12)^$D$4-1),0) -> 0
B32: 24 | C32: =IFERROR(ABS(PPMT($C$3/12,$B32,$D$4,$C$2)),0) -> 0 | D32: =IF(C32>0,E32-C32,0) -> 0 | E32: =IF(C32>0,$C$2*$C$3/12*(1+$C$3/12)^$D$4/((1+$C$3/12)^$D$4-1),0) -> 0
B33: 25 | C33: =IFERROR(ABS(PPMT($C$3/12,$B33,$D$4,$C$2)),0) -> 0 | D33: =IF(C33>0,E33-C33,0) -> 0 | E33: =IF(C33>0,$C$2*$C$3/12*(1+$C$3/12)^$D$4/((1+$C$3/12)^$D$4-1),0) -> 0
B34: 26 | C34: =IFERROR(ABS(PPMT($C$3/12,$B34,$D$4,$C$2)),0) -> 0 | D34: =IF(C34>0,E34-C34,0) -> 0 | E34: =IF(C34>0,$C$2*$C$3/12*(1+$C$3/12)^$D$4/((1+$C$3/12)^$D$4-1),0) -> 0
B35: 27 | C35: =IFERROR(ABS(PPMT($C$3/12,$B35,$D$4,$C$2)),0) -> 0 | D35: =IF(C35>0,E35-C35,0) -> 0 | E35: =IF(C35>0,$C$2*$C$3/12*(1+$C$3/12)^$D$4/((1+$C$3/12)^$D$4-1),0) -> 0
B36: 28 | C36: =IFERROR(ABS(PPMT($C$3/12,$B36,$D$4,$C$2)),0) -> 0 | D36: =IF(C36>0,E36-C36,0) -> 0 | E36: =IF(C36>0,$C$2*$C$3/12*(1+$C$3/12)^$D$4/((1+$C$3/12)^$D$4-1),0) -> 0
B37: 29 | C37: =IFERROR(ABS(PPMT($C$3/12,$B37,$D$4,$C$2)),0) -> 0 | D37: =IF(C37>0,E37-C37,0) -> 0 | E37: =IF(C37>0,$C$2*$C$3/12*(1+$C$3/12)^$D$4/((1+$C$3/12)^$D$4-1),0) -> 0
B38: 30 | C38: =IFERROR(ABS(PPMT($C$3/12,$B38,$D$4,$C$2)),0) -> 0 | D38: =IF(C38>0,E38-C38,0) -> 0 | E38: =IF(C38>0,$C$2*$C$3/12*(1+$C$3/12)^$D$4/((1+$C$3/12)^$D$4-1),0) -> 0
... B368: 360 | C368: =IFERROR(ABS(PPMT($C$3/12,$B368,$D$4,$C$2)),0) -> 0 | D368: =IF(C368>0,E368-C368,0) -> 0 | E368: =IF(C368>0,$C$2*$C$3/12*(1+$C$3/12)^$D$4/((1+$C$3/12)^$D$4-1),0) -> 0

Sheet 이자율계산
B2: 대출액 | C2: 2.1315024e+08 | D2: =C2 -> 2.1315024e+08 | I2: 대출액 | J2: 205310000 | K2: =J2 -> 205310000 | Q2: 대출액 | R2: 218760351 | S2: =R2 -> 218760351
B3: 이율(%) | C3: 0.05 | F3: 5년간 상환원금 | G3: =SUMIFS(C9:$C$368,$B$9:$B$368,"<=72") -> 66798018 | I3: 이율(%) | J3: 0.035 | Q3: 이율(%) | R3: 0.04
B4: 상환기간(년) | C4: 15 | D4: =C4*12 -> 180 | F4: 5년간 상환이자 | G4: =SUMIFS(D9:$D$368,$B$9:$B$368,"<=72") -> 54563634 | I4: 상환기간(년) | J4: 30 | K4: =J4*12 -> 360 | Q4: 상환기간(년) | R4: 15 | S4: =R4*12 -> 180
B5: 총 대출이자 | C5: =E9*D4-C2 -> 90253892 | F5: 5년후 잔여원금 | G5: =C2-SUMIFS(C9:$C$368,$B$9:$B$368,"<=72") -> 146352221 | I5: 총 대출이자 | J5: =L9*K4-J2 -> 1.2658611e+08 | N5: 총 대출이자 | O5: =G4+J5 -> 1.8114975e+08 | Q5: 총 대출이자 | R5: =T9*S4-R2 -> 72505551
B6: 월평균상환액 | C6: =E9 -> 1685578.5 | I6: 월평균상환액 | J6: =L9 -> 921933.65 | N6: 월상환액 | O6: =C6 -> 1685578.5 | Q6: 월평균상환액 | R6: =T9 -> 1618143.9
B8: 회차 | C8: 원금 | D8: 이자 | E8: 월불입금 | I8: 회차 | J8: 원금 | K8: 이자 | L8: 월불입금 | Q8: 회차 | R8: 원금 | S8: 이자 | T8: 월불입금
B9: 1 | C9: =IFERROR(ABS(PPMT($C$3/12,$B9,$D$4,$C$2)),0) -> 797452.51 | D9: =IF(C9>0,E9-C9,0) -> 888126 | E9: =IF(C9>0,$C$2*$C$3/12*(1+$C$3/12)^$D$4/((1+$C$3/12)^$D$4-1),0) -> 1685578.5 | I9: 1 | J9: =IFERROR(ABS(PPMT($J$3/12,$I9,$K$4,$J$2)),0) -> 323112.82 | K9: =IF(J9>0,L9-J9,0) -> 598820.83 | L9: =IF(J9>0,$J$2*$J$3/12*(1+$J$3/12)^$K$4/((1+$J$3/12)^$K$4-1),0) -> 921933.65 | Q9: 1 | R9: =IFERROR(ABS(PPMT($R$3/12,$Q9,$S$4,$R$2)),0) -> 888942.73 | S9: =IF(R9>0,T9-R9,0) -> 729201.17 | T9: =IF(R9>0,$R$2*$R$3/12*(1+$R$3/12)^$S$4/((1+$R$3/12)^$S$4-1),0) -> 1618143.9
B10: 2 | C10: =IFERROR(ABS(PPMT($C$3/12,$B10,$D$4,$C$2)),0) -> 800775.23 | D10: =IF(C10>0,E10-C10,0) -> 884803.28 | E10: =IF(C10>0,$C$2*$C$3/12*(1+$C$3/12)^$D$4/((1+$C$3/12)^$D$4-1),0) -> 1685578.5 | I10: 2 | J10: =IFERROR(ABS(PPMT($J$3/12,$I10,$K$4,$J$2)),0) -> 324055.23 | K10: =IF(J10>0,L10-J10,0) -> 597878.42 | L10: =IF(J10>0,$J$2*$J$3/12*(1+$J$3/12)^$K$4/((1+$J$3/12)^$K$4-1),0) -> 921933.65 | Q10: 2 | R10: =IFERROR(ABS(PPMT($R$3/12,$Q10,$S$4,$R$2)),0) -> 891905.87 | S10: =IF(R10>0,T10-R10,0) -> 726238.03 | T10: =IF(R10>0,$R$2*$R$3/12*(1+$R$3/12)^$S$4/((1+$R$3/12)^$S$4-1),0) -> 1618143.9
B11: 3 | C11: =IFERROR(ABS(PPMT($C$3/12,$B11,$D$4,$C$2)),0) -> 804111.79 | D11: =IF(C11>0,E11-C11,0) -> 881466.72 | E11: =IF(C11>0,$C$2*$C$3/12*(1+$C$3/12)^$D$4/((1+$C$3/12)^$D$4-1),0) -> 1685578.5 | I11: 3 | J11: =IFERROR(ABS(PPMT($J$3/12,$I11,$K$4,$J$2)),0) -> 325000.39 | K11: =IF(J11>0,L11-J11,0) -> 596933.26 | L11: =IF(J11>0,$J$2*$J$3/12*(1+$J$3/12)^$K$4/((1+$J$3/12)^$K$4-1),0) -> 921933.65 | Q11: 3 | R11: =IFERROR(ABS(PPMT($R$3/12,$Q11,$S$4,$R$2)),0) -> 894878.89 | S11: =IF(R11>0,T11-R11,0) -> 723265.01 | T11: =IF(R11>0,$R$2*$R$3/12*(1+$R$3/12)^$S$4/((1+$R$3/12)^$S$4-1),0) -> 1618143.9
B12: 4 | C12: =IFERROR(ABS(PPMT($C$3/12,$B12,$D$4,$C$2)),0) -> 807462.26 | D12: =IF(C12>0,E12-C12,0) -> 878116.25 | E12: =IF(C12>0,$C$2*$C$3/12*(1+$C$3/12)^$D$4/((1+$C$3/12)^$D$4-1),0) -> 1685578.5 | I12: 4 | J12: =IFERROR(ABS(PPMT($J$3/12,$I12,$K$4,$J$2)),0) -> 325948.31 | K12: =IF(J12>0,L12-J12,0) -> 595985.34 | L12: =IF(J12>0,$J$2*$J$3/12*(1+$J$3/12)^$K$4/((1+$J$3/12)^$K$4-1),0) -> 921933.65 | Q12: 4 | R12: =IFERROR(ABS(PPMT($R$3/12,$Q12,$S$4,$R$2)),0) -> 897861.82 | S12: =IF(R12>0,T12-R12,0) -> 720282.08 | T12: =IF(R12>0,$R$2*$R$3/12*(1+$R$3/12)^$S$4/((1+$R$3/12)^$S$4-1),0) -> 1618143.9
